<?xml version="1.0"?>
<sdf version="1.5">
  <model name="button">
    <pose>0 0 0.03 0 0 0</pose>
    <link name="base_link">
      <inertial>
        <inertia>
          <ixx>0.01</ixx>
          <ixy>0.0</ixy>
          <ixz>0.0</ixz>
          <iyy>0.01</iyy>
          <iyz>0.0</iyz>
          <izz>0.01</izz>
        </inertia>
        <mass>1.0</mass>
      </inertial>
      <visual name="visual">
        <geometry>
          <box>
            <size>0.07 0.07 0.06</size>
          </box>
        </geometry>
        <material>
          <script><uri>file://media/materials/scripts/gazebo.material</uri>
          <name>Gazebo/DarkGrey</name></script>
        </material>
      </visual>
      <collision name="collision">
        <geometry>
          <box>
            <size>0.07 0.07 0.06</size>
          </box>
        </geometry>
      </collision>
    </link>
    <joint name="joint" type="prismatic">
      <parent>base_link</parent>
      <child>top_link</child>
      <pose>0 0 0 0 0 0</pose>
      <axis>
        <limit>
          <lower>-0.020</lower>
          <upper>0.025</upper>
        </limit>
        <xyz>0.0 0.0 1.0</xyz>
        <dynamics>
          <spring_stiffness>-500</spring_stiffness>
          <spring_reference>-0.025</spring_reference>
          <damping>1.0</damping>
          <friction>1.0</friction>
        </dynamics>
      </axis>
    </joint>
    <link name="top_link">
      <pose>0 0 0 0 0 0</pose>
      <inertial>
        <inertia>
          <ixx>0.01</ixx>
          <ixy>0.0</ixy>
          <ixz>0.0</ixz>
          <iyy>0.01</iyy>
          <iyz>0.0</iyz>
          <izz>0.01</izz>
        </inertia>
        <mass>0.1</mass>
      </inertial>
      <visual name="visual">
        <pose>0 0 0.025 0 0 0</pose>
        <geometry>
          <box>
            <size>0.05 0.05 0.05</size>
          </box>
        </geometry>
        <material>
          <script>
            <uri>file://media/materials/scripts/gazebo.material</uri>
            <name>Gazebo/Red</name>
          </script>
        </material>
      </visual>
      <collision name="collision">
        <pose>0 0 0.025 0 0 0</pose>
        <geometry>
          <box>
            <size>0.05 0.05 0.05</size>
          </box>
        </geometry>
        <surface>
          <contact>
            <ode> 
              <kp>1e5</kp> 
              <kd>1</kd> 
              <max_vel>100.0</max_vel> 
              <min_depth>0.001</min_depth> 
            </ode> 
          </contact> 
        </surface> 
      </collision>
    </link>
  </model>
</sdf>