<?xml version="1.0" encoding="utf-8" ?>
<!-- =================================================================================== -->
<!-- |    This document was autogenerated by xacro from /root/ros_ws/src/ros_ur3/ur3_gazebo/urdf/ur_gripper_hande.xacro | -->
<!-- |    EDITING THIS FILE BY HAND IS NOT RECOMMENDED                                 | -->
<!-- =================================================================================== -->
<robot name="ur_robot_gazebo">
    <!--
    This is a top-level xacro instantiating the Gazebo-specific version of the
    'ur_robot' macro (ie: 'ur_robot_gazebo') and passing it values for all its
    required arguments.
    This file should be considered the Gazebo-specific variant of the file
    with the same name in the ur_description package. It accepts the same
    arguments, but instead of configuring everything for a real robot, will
    generate a Gazebo-compatible URDF with a ros_control hardware_interface
    attached to it.
    Only use this top-level xacro if you plan on spawning the robot in Gazebo
    'by itself', without any gripper or any other geometry attached.
    If you need to attach an end-effector, camera or need to integrate the
    robot into a larger workcell and want to spawn that as a single entity in
    Gazebo, DO NOT EDIT THIS FILE.
    Instead: create a new top-level xacro, give it a proper name, include the
    required '.xacro' files, instantiate the models (ie: call the macros) and
    connect everything by adding the appropriate joints.
  -->
    <!--
    Main xacro macro definition of the "Gazebo robot" model.

    This wraps the model of the real robot and adds all elements and parameters
    required by Gazebo.

    It also adds the gazebo_ros_control plugin.

    NOTE: this is NOT a URDF. It cannot directly be loaded by consumers
    expecting a flattened '.urdf' file. See the top-level '.xacro' for that
    (but note: that .xacro must still be processed by the xacro command).

    For use in '.launch' files: use one of the 'load_urX.launch' convenience
    launch files.

    NOTE: this Gazebo model makes use of the same set of parameter files as the
    main xacro macro (in ur_description). It is therefor possible to use the
    kinematic calibration exported from a REAL UR robot. Please refer to the
    ur_macro.xacro in ur_description for more information about this.

    Main author of the migration to yaml configs: Ludovic Delval.

    Contributors to previous versions (in no particular order):

     - Felix Messmer
     - Kelsey Hawkins
     - Shaun Edwards
     - Alexander Bubeck
     - Nadia Hammoudeh Garcia
     - G. vd. Hoorn
     - Dave Niewinski
     - Andy Zelenak
     - Miguel Prada
     - Mathias Luedtke
     - Hans-Joachim Krauch
     - Felix Exner
  -->
    <!--
    Base UR robot series xacro macro.

    NOTE: this is NOT a URDF. It cannot directly be loaded by consumers
    expecting a flattened '.urdf' file. See the top-level '.xacro' for that
    (but note: that .xacro must still be processed by the xacro command).

    For use in '.launch' files: use one of the 'load_urX.launch' convenience
    launch files.

    This file models the base kinematic chain of a UR robot, which then gets
    parameterised by various configuration files to convert it into a UR3(e),
    UR5(e), UR10(e) or UR16e.

    NOTE: the default kinematic parameters (ie: link lengths, frame locations,
    offets, etc) do not correspond to any particular robot. They are defaults
    only. There WILL be non-zero offsets between the Forward Kinematics results
    in TF (ie: robot_state_publisher) and the values reported by the Teach
    Pendant.

    For accurate (and robot-specific) transforms, the 'kinematics_parameters_file'
    parameter MUST point to a .yaml file containing the appropriate values for
    the targetted robot.

    If using the UniversalRobots/Universal_Robots_ROS_Driver, follow the steps
    described in the readme of that repository to extract the kinematic
    calibration from the controller and generate the required .yaml file.

    Main author of the migration to yaml configs: Ludovic Delval.

    Contributors to previous versions (in no particular order):

     - Felix Messmer
     - Kelsey Hawkins
     - Wim Meeussen
     - Shaun Edwards
     - Nadia Hammoudeh Garcia
     - Dave Hershberger
     - G. vd. Hoorn
     - Philip Long
     - Dave Coleman
     - Miguel Prada
     - Mathias Luedtke
     - Marcel Schnirring
     - Felix von Drigalski
     - Felix Exner
     - Jimmy Da Silva
     - Ajit Krisshna N L
     - Muhammad Asif Rana
  -->
    <!--
    NOTE: the macro defined in this file is NOT part of the public API of this
          package. Users CANNOT rely on this file being available, or stored in
          this location. Nor can they rely on the existence of the macro.
  -->
    <transmission name="shoulder_pan_trans">
        <type>transmission_interface/SimpleTransmission</type>
        <joint name="shoulder_pan_joint">
            <hardwareInterface>hardware_interface/PositionJointInterface</hardwareInterface>
        </joint>
        <actuator name="shoulder_pan_motor">
            <mechanicalReduction>1</mechanicalReduction>
        </actuator>
    </transmission>
    <transmission name="shoulder_lift_trans">
        <type>transmission_interface/SimpleTransmission</type>
        <joint name="shoulder_lift_joint">
            <hardwareInterface>hardware_interface/PositionJointInterface</hardwareInterface>
        </joint>
        <actuator name="shoulder_lift_motor">
            <mechanicalReduction>1</mechanicalReduction>
        </actuator>
    </transmission>
    <transmission name="elbow_trans">
        <type>transmission_interface/SimpleTransmission</type>
        <joint name="elbow_joint">
            <hardwareInterface>hardware_interface/PositionJointInterface</hardwareInterface>
        </joint>
        <actuator name="elbow_motor">
            <mechanicalReduction>1</mechanicalReduction>
        </actuator>
    </transmission>
    <transmission name="wrist_1_trans">
        <type>transmission_interface/SimpleTransmission</type>
        <joint name="wrist_1_joint">
            <hardwareInterface>hardware_interface/PositionJointInterface</hardwareInterface>
        </joint>
        <actuator name="wrist_1_motor">
            <mechanicalReduction>1</mechanicalReduction>
        </actuator>
    </transmission>
    <transmission name="wrist_2_trans">
        <type>transmission_interface/SimpleTransmission</type>
        <joint name="wrist_2_joint">
            <hardwareInterface>hardware_interface/PositionJointInterface</hardwareInterface>
        </joint>
        <actuator name="wrist_2_motor">
            <mechanicalReduction>1</mechanicalReduction>
        </actuator>
    </transmission>
    <transmission name="wrist_3_trans">
        <type>transmission_interface/SimpleTransmission</type>
        <joint name="wrist_3_joint">
            <hardwareInterface>hardware_interface/PositionJointInterface</hardwareInterface>
        </joint>
        <actuator name="wrist_3_motor">
            <mechanicalReduction>1</mechanicalReduction>
        </actuator>
    </transmission>
    <!-- links: main serial chain -->
    <link name="base_link" />
    <link name="base_link_inertia">
        <visual>
            <origin rpy="0 0 3.14159265359" xyz="0 0 0" />
            <geometry>
                <mesh filename="package://ur_description/meshes/ur3e/visual/base.dae" />
            </geometry>
            <material name="LightGrey">
                <color rgba="0.7 0.7 0.7 1.0" />
            </material>
        </visual>
        <collision>
            <origin rpy="0 0 3.14159265359" xyz="0 0 0" />
            <geometry>
                <mesh filename="package://ur_description/meshes/ur3e/collision/base.stl" />
            </geometry>
        </collision>
        
<inertial>
            <mass value="2.0" />
            <origin rpy="0 0 0" xyz="0 0 0" />
            <inertia ixx="0.0030531654454" ixy="0.0" ixz="0.0" iyy="0.0030531654454" iyz="0.0" izz="0.005625" />
        </inertial>

    </link>
    <link name="shoulder_link">
        <visual>
            <origin rpy="0 0 3.14159265359" xyz="0 0 0" />
            <geometry>
                <mesh filename="package://ur_description/meshes/ur3e/visual/shoulder.dae" />
            </geometry>
            <material name="LightGrey">
                <color rgba="0.7 0.7 0.7 1.0" />
            </material>
        </visual>
        <collision>
            <origin rpy="0 0 3.14159265359" xyz="0 0 0" />
            <geometry>
                <mesh filename="package://ur_description/meshes/ur3e/collision/shoulder.stl" />
            </geometry>
        </collision>
        
<inertial>
            <mass value="2.0" />
            <origin rpy="0 0 0" xyz="0 0 0" />
            <inertia ixx="0.0080931634294" ixy="0.0" ixz="0.0" iyy="0.0080931634294" iyz="0.0" izz="0.005625" />
        </inertial>

    </link>
    <link name="upper_arm_link">
        <visual>
            <origin rpy="1.57079632679 0 -1.57079632679" xyz="0 0 0.12" />
            <geometry>
                <mesh filename="package://ur_description/meshes/ur3e/visual/upperarm.dae" />
            </geometry>
            <material name="LightGrey">
                <color rgba="0.7 0.7 0.7 1.0" />
            </material>
        </visual>
        <collision>
            <origin rpy="1.57079632679 0 -1.57079632679" xyz="0 0 0.12" />
            <geometry>
                <mesh filename="package://ur_description/meshes/ur3e/collision/upperarm.stl" />
            </geometry>
        </collision>
        
<inertial>
            <mass value="3.42" />
            <origin rpy="0 1.57079632679 0" xyz="-0.121825 0.0 0.12" />
            <inertia ixx="0.0217284832211" ixy="0.0" ixz="0.0" iyy="0.0217284832211" iyz="0.0" izz="0.00961875" />
        </inertial>

    </link>
    <link name="forearm_link">
        <visual>
            <origin rpy="1.57079632679 0 -1.57079632679" xyz="0 0 0.027" />
            <geometry>
                <mesh filename="package://ur_description/meshes/ur3e/visual/forearm.dae" />
            </geometry>
            <material name="LightGrey">
                <color rgba="0.7 0.7 0.7 1.0" />
            </material>
        </visual>
        <collision>
            <origin rpy="1.57079632679 0 -1.57079632679" xyz="0 0 0.027" />
            <geometry>
                <mesh filename="package://ur_description/meshes/ur3e/collision/forearm.stl" />
            </geometry>
        </collision>
        
<inertial>
            <mass value="1.26" />
            <origin rpy="0 1.57079632679 0" xyz="-0.1066 0.0 0.027" />
            <inertia ixx="0.00654456758217" ixy="0.0" ixz="0.0" iyy="0.00654456758217" iyz="0.0" izz="0.00354375" />
        </inertial>

    </link>
    <link name="wrist_1_link">
        <visual>
            <!-- TODO: Move this to a parameter -->
            <origin rpy="1.57079632679 0 0" xyz="0 0 -0.104" />
            <geometry>
                <mesh filename="package://ur_description/meshes/ur3e/visual/wrist1.dae" />
            </geometry>
            <material name="LightGrey">
                <color rgba="0.7 0.7 0.7 1.0" />
            </material>
        </visual>
        <collision>
            <origin rpy="1.57079632679 0 0" xyz="0 0 -0.104" />
            <geometry>
                <mesh filename="package://ur_description/meshes/ur3e/collision/wrist1.stl" />
            </geometry>
        </collision>
        
<inertial>
            <mass value="0.8" />
            <origin rpy="0 0 0" xyz="0 0 0" />
            <inertia ixx="0.002084999166" ixy="0.0" ixz="0.0" iyy="0.002084999166" iyz="0.0" izz="0.00225" />
        </inertial>

    </link>
    <link name="wrist_2_link">
        <visual>
            <origin rpy="0 0 0" xyz="0 0 -0.08535" />
            <geometry>
                <mesh filename="package://ur_description/meshes/ur3e/visual/wrist2.dae" />
            </geometry>
            <material name="LightGrey">
                <color rgba="0.7 0.7 0.7 1.0" />
            </material>
        </visual>
        <collision>
            <origin rpy="0 0 0" xyz="0 0 -0.08535" />
            <geometry>
                <mesh filename="package://ur_description/meshes/ur3e/collision/wrist2.stl" />
            </geometry>
        </collision>
        
<inertial>
            <mass value="0.8" />
            <origin rpy="0 0 0" xyz="0 0 0" />
            <inertia ixx="0.002084999166" ixy="0.0" ixz="0.0" iyy="0.002084999166" iyz="0.0" izz="0.00225" />
        </inertial>

    </link>
    <link name="wrist_3_link">
        <visual>
            <origin rpy="1.57079632679 0 0" xyz="0 0 -0.0921" />
            <geometry>
                <mesh filename="package://ur_description/meshes/ur3e/visual/wrist3.dae" />
            </geometry>
            <material name="LightGrey">
                <color rgba="0.7 0.7 0.7 1.0" />
            </material>
        </visual>
        <collision>
            <origin rpy="1.57079632679 0 0" xyz="0 0 -0.0921" />
            <geometry>
                <mesh filename="package://ur_description/meshes/ur3e/collision/wrist3.stl" />
            </geometry>
        </collision>
        
<inertial>
            <mass value="0.35" />
            <origin rpy="0 0 0" xyz="0.0 0.0 -0.02" />
            <inertia ixx="0.00013626661216" ixy="0.0" ixz="0.0" iyy="0.00013626661216" iyz="0.0" izz="0.0001792" />
        </inertial>

    </link>
    <!-- joints: main serial chain -->
    <joint name="base_link-base_link_inertia" type="fixed">
        <parent link="base_link" />
        <child link="base_link_inertia" />
        <!-- 'base_link' is REP-103 aligned (so X+ forward), while the internal
           frames of the robot/controller have X+ pointing backwards.
           Use the joint between 'base_link' and 'base_link_inertia' (a dummy
           link/frame) to introduce the necessary rotation over Z (of pi rad).
      -->
        <origin rpy="0 0 3.14159265359" xyz="0 0 0" />
    </joint>
    <joint name="shoulder_pan_joint" type="revolute">
        <parent link="base_link_inertia" />
        <child link="shoulder_link" />
        <origin rpy="0 0 0" xyz="0 0 0.15185" />
        <axis xyz="0 0 1" />
        <limit effort="56.0" lower="-6.28318530718" upper="6.28318530718" velocity="3.14159265359" />
        <dynamics damping="0" friction="0" />
    </joint>
    <joint name="shoulder_lift_joint" type="revolute">
        <parent link="shoulder_link" />
        <child link="upper_arm_link" />
        <origin rpy="1.570796327 0 0" xyz="0 0 0" />
        <axis xyz="0 0 1" />
        <limit effort="56.0" lower="-6.28318530718" upper="6.28318530718" velocity="3.14159265359" />
        <dynamics damping="0" friction="0" />
    </joint>
    <joint name="elbow_joint" type="revolute">
        <parent link="upper_arm_link" />
        <child link="forearm_link" />
        <origin rpy="0 0 0" xyz="-0.24355 0 0" />
        <axis xyz="0 0 1" />
        <limit effort="28.0" lower="-3.14159265359" upper="3.14159265359" velocity="3.14159265359" />
        <dynamics damping="0" friction="0" />
    </joint>
    <joint name="wrist_1_joint" type="revolute">
        <parent link="forearm_link" />
        <child link="wrist_1_link" />
        <origin rpy="0 0 0" xyz="-0.2132 0 0.13105" />
        <axis xyz="0 0 1" />
        <limit effort="12.0" lower="-6.28318530718" upper="6.28318530718" velocity="6.28318530718" />
        <dynamics damping="0" friction="0" />
    </joint>
    <joint name="wrist_2_joint" type="revolute">
        <parent link="wrist_1_link" />
        <child link="wrist_2_link" />
        <origin rpy="1.570796327 0 0" xyz="0 -0.08535 -1.75055776238e-11" />
        <axis xyz="0 0 1" />
        <limit effort="12.0" lower="-6.28318530718" upper="6.28318530718" velocity="6.28318530718" />
        <dynamics damping="0" friction="0" />
    </joint>
    <joint name="wrist_3_joint" type="revolute">
        <parent link="wrist_2_link" />
        <child link="wrist_3_link" />
        <origin rpy="1.57079632659 3.14159265359 3.14159265359" xyz="0 0.0921 -1.88900257663e-11" />
        <axis xyz="0 0 1" />
        <limit effort="12.0" lower="-6.28318530718" upper="6.28318530718" velocity="6.28318530718" />
        <dynamics damping="0" friction="0" />
    </joint>
    <!-- ROS-Industrial 'base' frame: base_link to UR 'Base' Coordinates transform -->
    <link name="base" />
    <joint name="base_link-base_fixed_joint" type="fixed">
        <!-- Note the rotation over Z of pi radians: as base_link is REP-103
           aligned (ie: has X+ forward, Y+ left and Z+ up), this is needed
           to correctly align 'base' with the 'Base' coordinate system of
           the UR controller.
      -->
        <origin rpy="0 0 3.14159265359" xyz="0 0 0" />
        <parent link="base_link" />
        <child link="base" />
    </joint>
    <!-- ROS-Industrial 'flange' frame: attachment point for EEF models -->
    <link name="flange" />
    <joint name="wrist_3-flange" type="fixed">
        <parent link="wrist_3_link" />
        <child link="flange" />
        <origin rpy="0 -1.57079632679 -1.57079632679" xyz="0 0 0" />
    </joint>
    <!-- ROS-Industrial 'tool0' frame: all-zeros tool frame -->
    <link name="tool0" />
    <joint name="flange-tool0" type="fixed">
        <!-- default toolframe: X+ left, Y+ up, Z+ front -->
        <origin rpy="1.57079632679 0 1.57079632679" xyz="0 0 0" />
        <parent link="flange" />
        <child link="tool0" />
    </joint>
    <!-- Configure self collision properties per link -->
    <gazebo reference="shoulder_link">
        <selfCollide>true</selfCollide>
    </gazebo>
    <gazebo reference="upper_arm_link">
        <selfCollide>true</selfCollide>
    </gazebo>
    <gazebo reference="forearm_link">
        <selfCollide>true</selfCollide>
    </gazebo>
    <gazebo reference="wrist_1_link">
        <selfCollide>true</selfCollide>
    </gazebo>
    <gazebo reference="wrist_3_link">
        <selfCollide>true</selfCollide>
    </gazebo>
    <gazebo reference="wrist_2_link">
        <selfCollide>true</selfCollide>
    </gazebo>
    <gazebo reference="ee_link">
        <selfCollide>true</selfCollide>
    </gazebo>
    <!--
      Inject Gazebo ROS Control plugin, which allows us to use ros_control
      controllers to control the virtual robot hw.
    -->
    <gazebo>
        <plugin filename="libgazebo_ros_control.so" name="ros_control">
            <!--robotNamespace>/</robotNamespace-->
            <!--robotSimType>gazebo_ros_control/DefaultRobotHWSim</robotSimType-->
        </plugin>
    </gazebo>
    <!--
    Attach the Gazebo model to Gazebo's world frame.
    Note: if you're looking to integrate a UR into a larger scene and need
    to add EEFs or other parts, DO NOT change this file or the 'world' link
    here. Create a NEW xacro instead and decide whether you need to add
    a 'world' link there.
  -->
    <link name="world" />
    <joint name="world_joint" type="fixed">
        <parent link="world" />
        <child link="base_link" />
        <origin rpy="0 0 0" xyz="0 0 0" />
    </joint>
    <!-- Gripper -->
    <!--
  Author: Cristian Beltran
-->
    <!-- Robotiq Coupler -->
    <!--  + Height added by the coupler: 8mm -->
    <!--  + Reference frame: at the middle (4mm) -->
    <link name="robotiq_coupler">
        <visual>
            <geometry>
                <mesh filename="package://robotiq_description/meshes/robotiq_85_coupler.stl" />
            </geometry>
            <material name="flat_black" />
        </visual>
        <collision>
            <geometry>
                <mesh filename="package://robotiq_description/meshes/robotiq_85_coupler.stl" />
            </geometry>
        </collision>
        
<inertial>
            <origin rpy="0 0 0" xyz="2.073e-05   1.45286e-03  -1.1049e-03" />
            <mass value="0.168" />
            <inertia ixx="6.69695624e-05" ixy="5.21511788e-09" ixz="-2.74383009e-08" iyy="7.85088161e-05" iyz="5.41105193e-07" izz="1.41819717e-04" />
        </inertial>

    </link>
    <joint name="robotiq_coupler_joint" type="fixed">
        <origin rpy="0 0 -1.57079632679" xyz="0 0 0.004" />
        <parent link="tool0" />
        <child link="robotiq_coupler" />
    </joint>
    <gazebo reference="robotiq_coupler">
        <mu1>0.9</mu1>
        <mu2>0.9</mu2>
        <material>Gazebo/FlatBlack</material>
    </gazebo>
    <!-- Equivalent to the OpenRAVE manipulator denso_robotiq_hande_gripper -->
    <link name="ur_gripper_tip_link" />
    <joint name="manipulator_dummy_joint" type="fixed">
        <origin rpy="0 0 0" xyz="0 0 0.1441" />
        <parent link="robotiq_coupler" />
        <child link="ur_gripper_tip_link" />
    </joint>
    <joint name="robotiq_hande_base_joint" type="fixed">
        <parent link="robotiq_coupler" />
        <child link="hand_e_link" />
        <origin rpy="0 0 -1.57079632679" xyz="0 0 0.004" />
    </joint>
    <link name="hand_e_link">
        
<inertial>
            <origin rpy="0 0 0" xyz="0 0 0.04607" />
            <mass value="0.86387" />
            <inertia ixx="1017560E-9" ixy="0" ixz="2235E-9" iyy="1028041E-9" iyz="0" izz="489810E-9" />
        </inertial>

        <visual>
            <origin rpy="0 0 0" xyz="0 0 0" />
            <geometry>
                <mesh filename="package://robotiq_description/meshes/hande/hand-e.dae" scale="1.0 1.0 1.0" />
            </geometry>
            <material name="Dark">
                <color rgba=".1 0.1 0.1 1.0" />
            </material>
        </visual>
        <collision>
            <origin rpy="0 0 0" xyz="0 0 0" />
            <geometry>
                <mesh filename="package://robotiq_description/meshes/hande/hand-e-collision.dae" scale="1.0 1.0 1.0" />
            </geometry>
        </collision>
    </link>
    <link name="hande_left_finger">
        
<inertial>
            <origin rpy="0 0 0" xyz="0.02262 -0.00759 0.00738" />
            <mass value="0.03804" />
            <inertia ixx="13567E-9" ixy="1849E-9" ixz="3622E-9" iyy="15784E-9" iyz="3616E-9" izz="7478E-9" />
        </inertial>

        <visual>
            <origin rpy="0 0 0" xyz="0 0 0" />
            <geometry>
                <mesh filename="package://robotiq_description/meshes/hande/finger_1.dae" scale="1.0 1.0 1.0" />
            </geometry>
            <material name="DarkGray">
                <color rgba=".4 0.4 0.4 1.0" />
            </material>
        </visual>
        <collision>
            <origin rpy="0 0 0" xyz="0 0 0" />
            <geometry>
                <mesh filename="package://robotiq_description/meshes/hande/finger_1-collision.dae" scale="1.0 1.0 1.0" />
            </geometry>
        </collision>
    </link>
    <link name="hande_right_finger">
        
<inertial>
            <origin rpy="0 0 0" xyz="-0.02262 0.00759 0.00738" />
            <mass value="0.03804" />
            <inertia ixx="13567E-9" ixy="1849E-9" ixz="-3622E-9" iyy="15784E-9" iyz="-3616E-9" izz="7478E-9" />
        </inertial>

        <visual>
            <origin rpy="0 0 0" xyz="0 0 0" />
            <geometry>
                <mesh filename="package://robotiq_description/meshes/hande/finger_2.dae" scale="1.0 1.0 1.0" />
            </geometry>
            <material name="DarkGray">
                <color rgba=".4 0.4 0.4 1.0" />
            </material>
        </visual>
        <collision>
            <origin rpy="0 0 0" xyz="0 0 0" />
            <geometry>
                <mesh filename="package://robotiq_description/meshes/hande/finger_2-collision.dae" scale="1.0 1.0 1.0" />
            </geometry>
        </collision>
    </link>
    <gazebo reference="hand_e_link">
        <material>Gazebo/FlatBlack</material>
    </gazebo>
    <gazebo reference="hande_right_finger">
        <material>Gazebo/Grey</material>
    </gazebo>
    <gazebo reference="hande_left_finger">
        <material>Gazebo/Grey</material>
    </gazebo>
    <joint name="hande_left_finger_joint" type="prismatic">
        <origin rpy="0 0 0" xyz="0 0 0.099" />
        <parent link="hand_e_link" />
        <child link="hande_left_finger" />
        <axis xyz="-1 0 0" />
        <limit effort="130" lower="0" upper="0.025" velocity="0.15" />
    </joint>
    <joint name="hande_right_finger_joint" type="prismatic">
        <origin rpy="0 0 0" xyz="0 0 0.099" />
        <parent link="hand_e_link" />
        <child link="hande_right_finger" />
        <axis xyz="1 0 0" />
        <limit effort="130" lower="0" upper="0.025" velocity="0.15" />
        <mimic joint="hande_left_finger_joint" multiplier="1" offset="0" />
    </joint>
    <!-- Improve grasping physics -->
    <gazebo reference="hande_left_finger">
        <kp>1000000.0</kp>
        <kd>1.0</kd>
        <mu1>1.0</mu1>
        <mu2>1.0</mu2>
        <minDepth>0.001</minDepth>
    </gazebo>
    <gazebo reference="hande_right_finger">
        <kp>1000000.0</kp>
        <kd>1.0</kd>
        <mu1>1.0</mu1>
        <mu2>1.0</mu2>
        <minDepth>0.001</minDepth>
    </gazebo>
    <transmission name="hande_left_finger_trans">
        <type>transmission_interface/SimpleTransmission</type>
        <joint name="hande_left_finger_joint">
            <hardwareInterface>hardware_interface/PositionJointInterface</hardwareInterface>
        </joint>
        <actuator name="hande_left_finger_motor">
            <mechanicalReduction>1</mechanicalReduction>
        </actuator>
    </transmission>
    <!-- <transmission name="${prefix}hande_right_finger_trans">
      <type>transmission_interface/SimpleTransmission</type>
      <joint name="${prefix}hande_right_finger_joint">
        <hardwareInterface>hardware_interface/PositionJointInterface</hardwareInterface>
      </joint>
      <actuator name="${prefix}hande_right_finger_motor">
        <mechanicalReduction>1</mechanicalReduction>
      </actuator>
    </transmission> -->
    <!-- Mimic joints -->
    <gazebo>
        <plugin filename="libgazebo_mimic_joint_plugin.so" name="mimic_robotiq_hande">
            <joint>hande_left_finger_joint</joint>
            <mimicJoint>hande_right_finger_joint</mimicJoint>
            <multiplier>1.0</multiplier>
            <offset>0.0</offset>
        </plugin>
    </gazebo>
    <!-- Gazebo Force/Torque sensor plugin -->
    <gazebo reference="wrist_3_joint">
        <provideFeedback>true</provideFeedback>
    </gazebo>
    <!-- <gazebo reference="wrist_3_joint">
    <preserveFixedJoint>true</preserveFixedJoint>
  </gazebo> -->
    <gazebo>
        <plugin filename="libgazebo_ros_ft_sensor.so" name="ft_sensor">
            <updateRate>500.0</updateRate>
            <topicName>wrench</topicName>
            <gaussianNoise>0.0</gaussianNoise>
            <jointName>wrist_3_joint</jointName>
        </plugin>
    </gazebo>
    <gazebo>
        <gripper name="gazebo_gripper">
            <grasp_check>
                <attach_steps>2</attach_steps>
                <detach_steps>2</detach_steps>
                <min_contact_count>3</min_contact_count>
            </grasp_check>
            <gripper_link>hande_right_finger</gripper_link>
            <gripper_link>hande_left_finger</gripper_link>
            <palm_link>hand_e_link</palm_link>
        </gripper>
    </gazebo>
    <!-- Gazebo grasping plugin -->
    <transmission name="trans_shoulder_pan_joint">
        <type>transmission_interface/SimpleTransmission</type>
        <joint name="shoulder_pan_joint">
            <hardwareInterface>hardware_interface/EffortJointInterface</hardwareInterface>
        </joint>
        <actuator name="shoulder_pan_joint_motor">
            <hardwareInterface>hardware_interface/EffortJointInterface</hardwareInterface>
            <mechanicalReduction>1</mechanicalReduction>
        </actuator>
    </transmission>
    <transmission name="trans_shoulder_lift_joint">
        <type>transmission_interface/SimpleTransmission</type>
        <joint name="shoulder_lift_joint">
            <hardwareInterface>hardware_interface/EffortJointInterface</hardwareInterface>
        </joint>
        <actuator name="shoulder_lift_joint_motor">
            <hardwareInterface>hardware_interface/EffortJointInterface</hardwareInterface>
            <mechanicalReduction>1</mechanicalReduction>
        </actuator>
    </transmission>
    <transmission name="trans_elbow_joint">
        <type>transmission_interface/SimpleTransmission</type>
        <joint name="elbow_joint">
            <hardwareInterface>hardware_interface/EffortJointInterface</hardwareInterface>
        </joint>
        <actuator name="elbow_joint_motor">
            <hardwareInterface>hardware_interface/EffortJointInterface</hardwareInterface>
            <mechanicalReduction>1</mechanicalReduction>
        </actuator>
    </transmission>
    <transmission name="trans_wrist_1_joint">
        <type>transmission_interface/SimpleTransmission</type>
        <joint name="wrist_1_joint">
            <hardwareInterface>hardware_interface/EffortJointInterface</hardwareInterface>
        </joint>
        <actuator name="wrist_1_joint_motor">
            <hardwareInterface>hardware_interface/EffortJointInterface</hardwareInterface>
            <mechanicalReduction>1</mechanicalReduction>
        </actuator>
    </transmission>
    <transmission name="trans_wrist_2_joint">
        <type>transmission_interface/SimpleTransmission</type>
        <joint name="wrist_2_joint">
            <hardwareInterface>hardware_interface/EffortJointInterface</hardwareInterface>
        </joint>
        <actuator name="wrist_2_joint_motor">
            <hardwareInterface>hardware_interface/EffortJointInterface</hardwareInterface>
            <mechanicalReduction>1</mechanicalReduction>
        </actuator>
    </transmission>
    <transmission name="trans_wrist_3_joint">
        <type>transmission_interface/SimpleTransmission</type>
        <joint name="wrist_3_joint">
            <hardwareInterface>hardware_interface/EffortJointInterface</hardwareInterface>
        </joint>
        <actuator name="wrist_3_joint_motor">
            <hardwareInterface>hardware_interface/EffortJointInterface</hardwareInterface>
            <mechanicalReduction>1</mechanicalReduction>
        </actuator>
    </transmission>
    <transmission name="trans_hande_left_finger_joint">
        <type>transmission_interface/SimpleTransmission</type>
        <joint name="hande_left_finger_joint">
            <hardwareInterface>hardware_interface/EffortJointInterface</hardwareInterface>
        </joint>
        <actuator name="hande_left_finger_joint_motor">
            <hardwareInterface>hardware_interface/EffortJointInterface</hardwareInterface>
            <mechanicalReduction>1</mechanicalReduction>
        </actuator>
    </transmission>
    <transmission name="trans_hande_right_finger_joint">
        <type>transmission_interface/SimpleTransmission</type>
        <joint name="hande_right_finger_joint">
            <hardwareInterface>hardware_interface/EffortJointInterface</hardwareInterface>
        </joint>
        <actuator name="hande_right_finger_joint_motor">
            <hardwareInterface>hardware_interface/EffortJointInterface</hardwareInterface>
            <mechanicalReduction>1</mechanicalReduction>
        </actuator>
    </transmission>
    <gazebo>
        <plugin name="gazebo_ros_control" filename="libgazebo_ros_control.so">
            <robotNamespace>/</robotNamespace>
        </plugin>
    </gazebo>
</robot>

<transmission name="shoulder_pan_trans">
        <type>transmission_interface/SimpleTransmission</type>
        <joint name="shoulder_pan_joint">
            <hardwareInterface>hardware_interface/PositionJointInterface</hardwareInterface>
        </joint>
        <actuator name="shoulder_pan_motor">
            <mechanicalReduction>1</mechanicalReduction>
        </actuator>
    </transmission>
    <transmission name="shoulder_lift_trans">
        <type>transmission_interface/SimpleTransmission</type>
        <joint name="shoulder_lift_joint">
            <hardwareInterface>hardware_interface/PositionJointInterface</hardwareInterface>
        </joint>
        <actuator name="shoulder_lift_motor">
            <mechanicalReduction>1</mechanicalReduction>
        </actuator>
    </transmission>
    <transmission name="elbow_trans">
        <type>transmission_interface/SimpleTransmission</type>
        <joint name="elbow_joint">
            <hardwareInterface>hardware_interface/PositionJointInterface</hardwareInterface>
        </joint>
        <actuator name="elbow_motor">
            <mechanicalReduction>1</mechanicalReduction>
        </actuator>
    </transmission>
    <transmission name="wrist_1_trans">
        <type>transmission_interface/SimpleTransmission</type>
        <joint name="wrist_1_joint">
            <hardwareInterface>hardware_interface/PositionJointInterface</hardwareInterface>
        </joint>
        <actuator name="wrist_1_motor">
            <mechanicalReduction>1</mechanicalReduction>
        </actuator>
    </transmission>
    <transmission name="wrist_2_trans">
        <type>transmission_interface/SimpleTransmission</type>
        <joint name="wrist_2_joint">
            <hardwareInterface>hardware_interface/PositionJointInterface</hardwareInterface>
        </joint>
        <actuator name="wrist_2_motor">
            <mechanicalReduction>1</mechanicalReduction>
        </actuator>
    </transmission>
    <transmission name="wrist_3_trans">
        <type>transmission_interface/SimpleTransmission</type>
        <joint name="wrist_3_joint">
            <hardwareInterface>hardware_interface/PositionJointInterface</hardwareInterface>
        </joint>
        <actuator name="wrist_3_motor">
            <mechanicalReduction>1</mechanicalReduction>
        </actuator>
    </transmission>
    <!-- links: main serial chain -->
    <link name="base_link" />
    <link name="base_link_inertia">
        <visual>
            <origin rpy="0 0 3.14159265359" xyz="0 0 0" />
            <geometry>
                <mesh filename="package://ur_description/meshes/ur3e/visual/base.dae" />
            </geometry>
            <material name="LightGrey">
                <color rgba="0.7 0.7 0.7 1.0" />
            </material>
        </visual>
        <collision>
            <origin rpy="0 0 3.14159265359" xyz="0 0 0" />
            <geometry>
                <mesh filename="package://ur_description/meshes/ur3e/collision/base.stl" />
            </geometry>
        </collision>
        <inertial>
            <mass value="2.0" />
            <origin rpy="0 0 0" xyz="0 0 0" />
            <inertia ixx="0.0030531654454" ixy="0.0" ixz="0.0" iyy="0.0030531654454" iyz="0.0" izz="0.005625" />
        </inertial>
    </link>
    <link name="shoulder_link">
        <visual>
            <origin rpy="0 0 3.14159265359" xyz="0 0 0" />
            <geometry>
                <mesh filename="package://ur_description/meshes/ur3e/visual/shoulder.dae" />
            </geometry>
            <material name="LightGrey">
                <color rgba="0.7 0.7 0.7 1.0" />
            </material>
        </visual>
        <collision>
            <origin rpy="0 0 3.14159265359" xyz="0 0 0" />
            <geometry>
                <mesh filename="package://ur_description/meshes/ur3e/collision/shoulder.stl" />
            </geometry>
        </collision>
        <inertial>
            <mass value="2.0" />
            <origin rpy="0 0 0" xyz="0 0 0" />
            <inertia ixx="0.0080931634294" ixy="0.0" ixz="0.0" iyy="0.0080931634294" iyz="0.0" izz="0.005625" />
        </inertial>
    </link>
    <link name="upper_arm_link">
        <visual>
            <origin rpy="1.57079632679 0 -1.57079632679" xyz="0 0 0.12" />
            <geometry>
                <mesh filename="package://ur_description/meshes/ur3e/visual/upperarm.dae" />
            </geometry>
            <material name="LightGrey">
                <color rgba="0.7 0.7 0.7 1.0" />
            </material>
        </visual>
        <collision>
            <origin rpy="1.57079632679 0 -1.57079632679" xyz="0 0 0.12" />
            <geometry>
                <mesh filename="package://ur_description/meshes/ur3e/collision/upperarm.stl" />
            </geometry>
        </collision>
        <inertial>
            <mass value="3.42" />
            <origin rpy="0 1.57079632679 0" xyz="-0.121825 0.0 0.12" />
            <inertia ixx="0.0217284832211" ixy="0.0" ixz="0.0" iyy="0.0217284832211" iyz="0.0" izz="0.00961875" />
        </inertial>
    </link>
    <link name="forearm_link">
        <visual>
            <origin rpy="1.57079632679 0 -1.57079632679" xyz="0 0 0.027" />
            <geometry>
                <mesh filename="package://ur_description/meshes/ur3e/visual/forearm.dae" />
            </geometry>
            <material name="LightGrey">
                <color rgba="0.7 0.7 0.7 1.0" />
            </material>
        </visual>
        <collision>
            <origin rpy="1.57079632679 0 -1.57079632679" xyz="0 0 0.027" />
            <geometry>
                <mesh filename="package://ur_description/meshes/ur3e/collision/forearm.stl" />
            </geometry>
        </collision>
        <inertial>
            <mass value="1.26" />
            <origin rpy="0 1.57079632679 0" xyz="-0.1066 0.0 0.027" />
            <inertia ixx="0.00654456758217" ixy="0.0" ixz="0.0" iyy="0.00654456758217" iyz="0.0" izz="0.00354375" />
        </inertial>
    </link>
    <link name="wrist_1_link">
        <visual>
            <!-- TODO: Move this to a parameter -->
            <origin rpy="1.57079632679 0 0" xyz="0 0 -0.104" />
            <geometry>
                <mesh filename="package://ur_description/meshes/ur3e/visual/wrist1.dae" />
            </geometry>
            <material name="LightGrey">
                <color rgba="0.7 0.7 0.7 1.0" />
            </material>
        </visual>
        <collision>
            <origin rpy="1.57079632679 0 0" xyz="0 0 -0.104" />
            <geometry>
                <mesh filename="package://ur_description/meshes/ur3e/collision/wrist1.stl" />
            </geometry>
        </collision>
        <inertial>
            <mass value="0.8" />
            <origin rpy="0 0 0" xyz="0 0 0" />
            <inertia ixx="0.002084999166" ixy="0.0" ixz="0.0" iyy="0.002084999166" iyz="0.0" izz="0.00225" />
        </inertial>
    </link>
    <link name="wrist_2_link">
        <visual>
            <origin rpy="0 0 0" xyz="0 0 -0.08535" />
            <geometry>
                <mesh filename="package://ur_description/meshes/ur3e/visual/wrist2.dae" />
            </geometry>
            <material name="LightGrey">
                <color rgba="0.7 0.7 0.7 1.0" />
            </material>
        </visual>
        <collision>
            <origin rpy="0 0 0" xyz="0 0 -0.08535" />
            <geometry>
                <mesh filename="package://ur_description/meshes/ur3e/collision/wrist2.stl" />
            </geometry>
        </collision>
        <inertial>
            <mass value="0.8" />
            <origin rpy="0 0 0" xyz="0 0 0" />
            <inertia ixx="0.002084999166" ixy="0.0" ixz="0.0" iyy="0.002084999166" iyz="0.0" izz="0.00225" />
        </inertial>
    </link>
    <link name="wrist_3_link">
        <visual>
            <origin rpy="1.57079632679 0 0" xyz="0 0 -0.0921" />
            <geometry>
                <mesh filename="package://ur_description/meshes/ur3e/visual/wrist3.dae" />
            </geometry>
            <material name="LightGrey">
                <color rgba="0.7 0.7 0.7 1.0" />
            </material>
        </visual>
        <collision>
            <origin rpy="1.57079632679 0 0" xyz="0 0 -0.0921" />
            <geometry>
                <mesh filename="package://ur_description/meshes/ur3e/collision/wrist3.stl" />
            </geometry>
        </collision>
        <inertial>
            <mass value="0.35" />
            <origin rpy="0 0 0" xyz="0.0 0.0 -0.02" />
            <inertia ixx="0.00013626661216" ixy="0.0" ixz="0.0" iyy="0.00013626661216" iyz="0.0" izz="0.0001792" />
        </inertial>
    </link>
    <!-- joints: main serial chain -->
    <joint name="base_link-base_link_inertia" type="fixed">
        <parent link="base_link" />
        <child link="base_link_inertia" />
        <!-- 'base_link' is REP-103 aligned (so X+ forward), while the internal
           frames of the robot/controller have X+ pointing backwards.
           Use the joint between 'base_link' and 'base_link_inertia' (a dummy
           link/frame) to introduce the necessary rotation over Z (of pi rad).
      -->
        <origin rpy="0 0 3.14159265359" xyz="0 0 0" />
    </joint>
    <joint name="shoulder_pan_joint" type="revolute">
        <parent link="base_link_inertia" />
        <child link="shoulder_link" />
        <origin rpy="0 0 0" xyz="0 0 0.15185" />
        <axis xyz="0 0 1" />
        <limit effort="56.0" lower="-6.28318530718" upper="6.28318530718" velocity="3.14159265359" />
        <dynamics damping="0" friction="0" />
    </joint>
    <joint name="shoulder_lift_joint" type="revolute">
        <parent link="shoulder_link" />
        <child link="upper_arm_link" />
        <origin rpy="1.570796327 0 0" xyz="0 0 0" />
        <axis xyz="0 0 1" />
        <limit effort="56.0" lower="-6.28318530718" upper="6.28318530718" velocity="3.14159265359" />
        <dynamics damping="0" friction="0" />
    </joint>
    <joint name="elbow_joint" type="revolute">
        <parent link="upper_arm_link" />
        <child link="forearm_link" />
        <origin rpy="0 0 0" xyz="-0.24355 0 0" />
        <axis xyz="0 0 1" />
        <limit effort="28.0" lower="-3.14159265359" upper="3.14159265359" velocity="3.14159265359" />
        <dynamics damping="0" friction="0" />
    </joint>
    <joint name="wrist_1_joint" type="revolute">
        <parent link="forearm_link" />
        <child link="wrist_1_link" />
        <origin rpy="0 0 0" xyz="-0.2132 0 0.13105" />
        <axis xyz="0 0 1" />
        <limit effort="12.0" lower="-6.28318530718" upper="6.28318530718" velocity="6.28318530718" />
        <dynamics damping="0" friction="0" />
    </joint>
    <joint name="wrist_2_joint" type="revolute">
        <parent link="wrist_1_link" />
        <child link="wrist_2_link" />
        <origin rpy="1.570796327 0 0" xyz="0 -0.08535 -1.75055776238e-11" />
        <axis xyz="0 0 1" />
        <limit effort="12.0" lower="-6.28318530718" upper="6.28318530718" velocity="6.28318530718" />
        <dynamics damping="0" friction="0" />
    </joint>
    <joint name="wrist_3_joint" type="revolute">
        <parent link="wrist_2_link" />
        <child link="wrist_3_link" />
        <origin rpy="1.57079632659 3.14159265359 3.14159265359" xyz="0 0.0921 -1.88900257663e-11" />
        <axis xyz="0 0 1" />
        <limit effort="12.0" lower="-6.28318530718" upper="6.28318530718" velocity="6.28318530718" />
        <dynamics damping="0" friction="0" />
    </joint>
    <!-- ROS-Industrial 'base' frame: base_link to UR 'Base' Coordinates transform -->
    <link name="base" />
    <joint name="base_link-base_fixed_joint" type="fixed">
        <!-- Note the rotation over Z of pi radians: as base_link is REP-103
           aligned (ie: has X+ forward, Y+ left and Z+ up), this is needed
           to correctly align 'base' with the 'Base' coordinate system of
           the UR controller.
      -->
        <origin rpy="0 0 3.14159265359" xyz="0 0 0" />
        <parent link="base_link" />
        <child link="base" />
    </joint>
    <!-- ROS-Industrial 'flange' frame: attachment point for EEF models -->
    <link name="flange" />
    <joint name="wrist_3-flange" type="fixed">
        <parent link="wrist_3_link" />
        <child link="flange" />
        <origin rpy="0 -1.57079632679 -1.57079632679" xyz="0 0 0" />
    </joint>
    <!-- ROS-Industrial 'tool0' frame: all-zeros tool frame -->
    <link name="tool0" />
    <joint name="flange-tool0" type="fixed">
        <!-- default toolframe: X+ left, Y+ up, Z+ front -->
        <origin rpy="1.57079632679 0 1.57079632679" xyz="0 0 0" />
        <parent link="flange" />
        <child link="tool0" />
    </joint>
    <!-- Configure self collision properties per link -->
    <gazebo reference="shoulder_link">
        <selfCollide>true</selfCollide>
    </gazebo>
    <gazebo reference="upper_arm_link">
        <selfCollide>true</selfCollide>
    </gazebo>
    <gazebo reference="forearm_link">
        <selfCollide>true</selfCollide>
    </gazebo>
    <gazebo reference="wrist_1_link">
        <selfCollide>true</selfCollide>
    </gazebo>
    <gazebo reference="wrist_3_link">
        <selfCollide>true</selfCollide>
    </gazebo>
    <gazebo reference="wrist_2_link">
        <selfCollide>true</selfCollide>
    </gazebo>
    <gazebo reference="ee_link">
        <selfCollide>true</selfCollide>
    </gazebo>
    <!--
      Inject Gazebo ROS Control plugin, which allows us to use ros_control
      controllers to control the virtual robot hw.
    -->
    <gazebo>
        <plugin filename="libgazebo_ros_control.so" name="ros_control">
            <!--robotNamespace>/</robotNamespace-->
            <!--robotSimType>gazebo_ros_control/DefaultRobotHWSim</robotSimType-->
        </plugin>
    </gazebo>
    <!--
    Attach the Gazebo model to Gazebo's world frame.
    Note: if you're looking to integrate a UR into a larger scene and need
    to add EEFs or other parts, DO NOT change this file or the 'world' link
    here. Create a NEW xacro instead and decide whether you need to add
    a 'world' link there.
  -->
    <link name="world" />
    <joint name="world_joint" type="fixed">
        <parent link="world" />
        <child link="base_link" />
        <origin rpy="0 0 0" xyz="0 0 0" />
    </joint>
    <!-- Gripper -->
    <!--
  Author: Cristian Beltran
-->
    <!-- Robotiq Coupler -->
    <!--  + Height added by the coupler: 8mm -->
    <!--  + Reference frame: at the middle (4mm) -->
    <link name="robotiq_coupler">
        <visual>
            <geometry>
                <mesh filename="package://robotiq_description/meshes/robotiq_85_coupler.stl" />
            </geometry>
            <material name="flat_black" />
        </visual>
        <collision>
            <geometry>
                <mesh filename="package://robotiq_description/meshes/robotiq_85_coupler.stl" />
            </geometry>
        </collision>
        <inertial>
            <origin rpy="0 0 0" xyz="2.073e-05   1.45286e-03  -1.1049e-03" />
            <mass value="0.168" />
            <inertia ixx="6.69695624e-05" ixy="5.21511788e-09" ixz="-2.74383009e-08" iyy="7.85088161e-05" iyz="5.41105193e-07" izz="1.41819717e-04" />
        </inertial>
    </link>
    <joint name="robotiq_coupler_joint" type="fixed">
        <origin rpy="0 0 -1.57079632679" xyz="0 0 0.004" />
        <parent link="tool0" />
        <child link="robotiq_coupler" />
    </joint>
    <gazebo reference="robotiq_coupler">
        <mu1>0.9</mu1>
        <mu2>0.9</mu2>
        <material>Gazebo/FlatBlack</material>
    </gazebo>
    <!-- Equivalent to the OpenRAVE manipulator denso_robotiq_hande_gripper -->
    <link name="ur_gripper_tip_link" />
    <joint name="manipulator_dummy_joint" type="fixed">
        <origin rpy="0 0 0" xyz="0 0 0.1441" />
        <parent link="robotiq_coupler" />
        <child link="ur_gripper_tip_link" />
    </joint>
    <joint name="robotiq_hande_base_joint" type="fixed">
        <parent link="robotiq_coupler" />
        <child link="hand_e_link" />
        <origin rpy="0 0 -1.57079632679" xyz="0 0 0.004" />
    </joint>
    <link name="hand_e_link">
        <inertial>
            <origin rpy="0 0 0" xyz="0 0 0.04607" />
            <mass value="0.86387" />
            <inertia ixx="1017560E-9" ixy="0" ixz="2235E-9" iyy="1028041E-9" iyz="0" izz="489810E-9" />
        </inertial>
        <visual>
            <origin rpy="0 0 0" xyz="0 0 0" />
            <geometry>
                <mesh filename="package://robotiq_description/meshes/hande/hand-e.dae" scale="1.0 1.0 1.0" />
            </geometry>
            <material name="Dark">
                <color rgba=".1 0.1 0.1 1.0" />
            </material>
        </visual>
        <collision>
            <origin rpy="0 0 0" xyz="0 0 0" />
            <geometry>
                <mesh filename="package://robotiq_description/meshes/hande/hand-e-collision.dae" scale="1.0 1.0 1.0" />
            </geometry>
        </collision>
    </link>
    <link name="hande_left_finger">
        <inertial>
            <origin rpy="0 0 0" xyz="0.02262 -0.00759 0.00738" />
            <mass value="0.03804" />
            <inertia ixx="13567E-9" ixy="1849E-9" ixz="3622E-9" iyy="15784E-9" iyz="3616E-9" izz="7478E-9" />
        </inertial>
        <visual>
            <origin rpy="0 0 0" xyz="0 0 0" />
            <geometry>
                <mesh filename="package://robotiq_description/meshes/hande/finger_1.dae" scale="1.0 1.0 1.0" />
            </geometry>
            <material name="DarkGray">
                <color rgba=".4 0.4 0.4 1.0" />
            </material>
        </visual>
        <collision>
            <origin rpy="0 0 0" xyz="0 0 0" />
            <geometry>
                <mesh filename="package://robotiq_description/meshes/hande/finger_1-collision.dae" scale="1.0 1.0 1.0" />
            </geometry>
        </collision>
    </link>
    <link name="hande_right_finger">
        <inertial>
            <origin rpy="0 0 0" xyz="-0.02262 0.00759 0.00738" />
            <mass value="0.03804" />
            <inertia ixx="13567E-9" ixy="1849E-9" ixz="-3622E-9" iyy="15784E-9" iyz="-3616E-9" izz="7478E-9" />
        </inertial>
        <visual>
            <origin rpy="0 0 0" xyz="0 0 0" />
            <geometry>
                <mesh filename="package://robotiq_description/meshes/hande/finger_2.dae" scale="1.0 1.0 1.0" />
            </geometry>
            <material name="DarkGray">
                <color rgba=".4 0.4 0.4 1.0" />
            </material>
        </visual>
        <collision>
            <origin rpy="0 0 0" xyz="0 0 0" />
            <geometry>
                <mesh filename="package://robotiq_description/meshes/hande/finger_2-collision.dae" scale="1.0 1.0 1.0" />
            </geometry>
        </collision>
    </link>
    <gazebo reference="hand_e_link">
        <material>Gazebo/FlatBlack</material>
    </gazebo>
    <gazebo reference="hande_right_finger">
        <material>Gazebo/Grey</material>
    </gazebo>
    <gazebo reference="hande_left_finger">
        <material>Gazebo/Grey</material>
    </gazebo>
    <joint name="hande_left_finger_joint" type="prismatic">
        <origin rpy="0 0 0" xyz="0 0 0.099" />
        <parent link="hand_e_link" />
        <child link="hande_left_finger" />
        <axis xyz="-1 0 0" />
        <limit effort="130" lower="0" upper="0.025" velocity="0.15" />
    </joint>
    <joint name="hande_right_finger_joint" type="prismatic">
        <origin rpy="0 0 0" xyz="0 0 0.099" />
        <parent link="hand_e_link" />
        <child link="hande_right_finger" />
        <axis xyz="1 0 0" />
        <limit effort="130" lower="0" upper="0.025" velocity="0.15" />
        <mimic joint="hande_left_finger_joint" multiplier="1" offset="0" />
    </joint>
    <!-- Improve grasping physics -->
    <gazebo reference="hande_left_finger">
        <kp>1000000.0</kp>
        <kd>1.0</kd>
        <mu1>1.0</mu1>
        <mu2>1.0</mu2>
        <minDepth>0.001</minDepth>
    </gazebo>
    <gazebo reference="hande_right_finger">
        <kp>1000000.0</kp>
        <kd>1.0</kd>
        <mu1>1.0</mu1>
        <mu2>1.0</mu2>
        <minDepth>0.001</minDepth>
    </gazebo>
    <transmission name="hande_left_finger_trans">
        <type>transmission_interface/SimpleTransmission</type>
        <joint name="hande_left_finger_joint">
            <hardwareInterface>hardware_interface/PositionJointInterface</hardwareInterface>
        </joint>
        <actuator name="hande_left_finger_motor">
            <mechanicalReduction>1</mechanicalReduction>
        </actuator>
    </transmission>
    <!-- <transmission name="${prefix}hande_right_finger_trans">
      <type>transmission_interface/SimpleTransmission</type>
      <joint name="${prefix}hande_right_finger_joint">
        <hardwareInterface>hardware_interface/PositionJointInterface</hardwareInterface>
      </joint>
      <actuator name="${prefix}hande_right_finger_motor">
        <mechanicalReduction>1</mechanicalReduction>
      </actuator>
    </transmission> -->
    <!-- Mimic joints -->
    <gazebo>
        <plugin filename="libgazebo_mimic_joint_plugin.so" name="mimic_robotiq_hande">
            <joint>hande_left_finger_joint</joint>
            <mimicJoint>hande_right_finger_joint</mimicJoint>
            <multiplier>1.0</multiplier>
            <offset>0.0</offset>
        </plugin>
    </gazebo>
    <!-- Gazebo Force/Torque sensor plugin -->
    <gazebo reference="wrist_3_joint">
        <provideFeedback>true</provideFeedback>
    </gazebo>
    <!-- <gazebo reference="wrist_3_joint">
    <preserveFixedJoint>true</preserveFixedJoint>
  </gazebo> -->
    <gazebo>
        <plugin filename="libgazebo_ros_ft_sensor.so" name="ft_sensor">
            <updateRate>500.0</updateRate>
            <topicName>wrench</topicName>
            <gaussianNoise>0.0</gaussianNoise>
            <jointName>wrist_3_joint</jointName>
        </plugin>
    </gazebo>
    <gazebo>
        <gripper name="gazebo_gripper">
            <grasp_check>
                <attach_steps>2</attach_steps>
                <detach_steps>2</detach_steps>
                <min_contact_count>3</min_contact_count>
            </grasp_check>
            <gripper_link>hande_right_finger</gripper_link>
            <gripper_link>hande_left_finger</gripper_link>
            <palm_link>hand_e_link</palm_link>
        </gripper>
    </gazebo>
    <!-- Gazebo grasping plugin -->
    <transmission name="trans_shoulder_pan_joint">
        <type>transmission_interface/SimpleTransmission</type>
        <joint name="shoulder_pan_joint">
            <hardwareInterface>hardware_interface/EffortJointInterface</hardwareInterface>
        </joint>
        <actuator name="shoulder_pan_joint_motor">
            <hardwareInterface>hardware_interface/EffortJointInterface</hardwareInterface>
            <mechanicalReduction>1</mechanicalReduction>
        </actuator>
    </transmission>
    <transmission name="trans_shoulder_lift_joint">
        <type>transmission_interface/SimpleTransmission</type>
        <joint name="shoulder_lift_joint">
            <hardwareInterface>hardware_interface/EffortJointInterface</hardwareInterface>
        </joint>
        <actuator name="shoulder_lift_joint_motor">
            <hardwareInterface>hardware_interface/EffortJointInterface</hardwareInterface>
            <mechanicalReduction>1</mechanicalReduction>
        </actuator>
    </transmission>
    <transmission name="trans_elbow_joint">
        <type>transmission_interface/SimpleTransmission</type>
        <joint name="elbow_joint">
            <hardwareInterface>hardware_interface/EffortJointInterface</hardwareInterface>
        </joint>
        <actuator name="elbow_joint_motor">
            <hardwareInterface>hardware_interface/EffortJointInterface</hardwareInterface>
            <mechanicalReduction>1</mechanicalReduction>
        </actuator>
    </transmission>
    <transmission name="trans_wrist_1_joint">
        <type>transmission_interface/SimpleTransmission</type>
        <joint name="wrist_1_joint">
            <hardwareInterface>hardware_interface/EffortJointInterface</hardwareInterface>
        </joint>
        <actuator name="wrist_1_joint_motor">
            <hardwareInterface>hardware_interface/EffortJointInterface</hardwareInterface>
            <mechanicalReduction>1</mechanicalReduction>
        </actuator>
    </transmission>
    <transmission name="trans_wrist_2_joint">
        <type>transmission_interface/SimpleTransmission</type>
        <joint name="wrist_2_joint">
            <hardwareInterface>hardware_interface/EffortJointInterface</hardwareInterface>
        </joint>
        <actuator name="wrist_2_joint_motor">
            <hardwareInterface>hardware_interface/EffortJointInterface</hardwareInterface>
            <mechanicalReduction>1</mechanicalReduction>
        </actuator>
    </transmission>
    <transmission name="trans_wrist_3_joint">
        <type>transmission_interface/SimpleTransmission</type>
        <joint name="wrist_3_joint">
            <hardwareInterface>hardware_interface/EffortJointInterface</hardwareInterface>
        </joint>
        <actuator name="wrist_3_joint_motor">
            <hardwareInterface>hardware_interface/EffortJointInterface</hardwareInterface>
            <mechanicalReduction>1</mechanicalReduction>
        </actuator>
    </transmission>
    <transmission name="trans_hande_left_finger_joint">
        <type>transmission_interface/SimpleTransmission</type>
        <joint name="hande_left_finger_joint">
            <hardwareInterface>hardware_interface/EffortJointInterface</hardwareInterface>
        </joint>
        <actuator name="hande_left_finger_joint_motor">
            <hardwareInterface>hardware_interface/EffortJointInterface</hardwareInterface>
            <mechanicalReduction>1</mechanicalReduction>
        </actuator>
    </transmission>
    <transmission name="trans_hande_right_finger_joint">
        <type>transmission_interface/SimpleTransmission</type>
        <joint name="hande_right_finger_joint">
            <hardwareInterface>hardware_interface/EffortJointInterface</hardwareInterface>
        </joint>
        <actuator name="hande_right_finger_joint_motor">
            <hardwareInterface>hardware_interface/EffortJointInterface</hardwareInterface>
            <mechanicalReduction>1</mechanicalReduction>
        </actuator>
    </transmission>
    <gazebo>
        <plugin name="gazebo_ros_control" filename="libgazebo_ros_control.so">
            <robotNamespace>/</robotNamespace>
        </plugin>
    </gazebo>
</robot>