<?xml version="1.0" encoding="utf-8"?>
<!-- =================================================================================== -->
<!-- |    This document was autogenerated by xacro from ur3e_robotiq_hande_gripper.urdf.xacro | -->
<!-- |    EDITING THIS FILE BY HAND IS NOT RECOMMENDED                                 | -->
<!-- =================================================================================== -->
<robot name="ur3">
  <gazebo>
    <plugin filename="libgazebo_ros_control.so" name="gazebo_ros_control">
      <!-- <robotNamespace>/</robotNamespace>
      <robotSimType>gazebo_ros_control/DefaultRobotHWSim</robotSimType>
      <legacyModeNS>true</legacyModeNS> -->
    </plugin>
  </gazebo>
  <!--
  Author: Felix Messmer
-->
  <!-- measured from model -->
  <link name="base_link">
    <visual>
      <geometry>
        <mesh filename="package://ur_e_description/meshes/ur3e/visual/base.dae"/>
      </geometry>
      <material name="LightGrey">
        <color rgba="0.7 0.7 0.7 1.0"/>
      </material>
    </visual>
    <collision>
      <geometry>
        <mesh filename="package://ur_e_description/meshes/ur3e/collision/base.stl"/>
      </geometry>
    </collision>
    <inertial>
      <mass value="2.0"/>
      <origin rpy="0 0 0" xyz="0.0 0.0 0.0"/>
      <inertia ixx="0.0030531654454" ixy="0.0" ixz="0.0" iyy="0.0030531654454" iyz="0.0" izz="0.005625"/>
    </inertial>
  </link>
  <joint name="shoulder_pan_joint" type="revolute">
    <parent link="base_link"/>
    <child link="shoulder_link"/>
    <origin rpy="0.0 0.0 0.0" xyz="0.0 0.0 0.152"/>
    <axis xyz="0 0 1"/>
    <limit effort="330.0" lower="-6.28318530718" upper="6.28318530718" velocity="3.14"/>
    <dynamics damping="0.0" friction="0.0"/>
  </joint>
  <link name="shoulder_link">
    <visual>
      <geometry>
        <mesh filename="package://ur_e_description/meshes/ur3e/visual/shoulder.dae"/>
      </geometry>
      <material name="LightGrey">
        <color rgba="0.7 0.7 0.7 1.0"/>
      </material>
    </visual>
    <collision>
      <geometry>
        <mesh filename="package://ur_e_description/meshes/ur3e/collision/shoulder.stl"/>
      </geometry>
    </collision>
    <inertial>
      <mass value="2.0"/>
      <origin rpy="0 0 0" xyz="0.0 0.0 0.0"/>
      <inertia ixx="0.0080931634294" ixy="0.0" ixz="0.0" iyy="0.0080931634294" iyz="0.0" izz="0.005625"/>
    </inertial>
  </link>
  <joint name="shoulder_lift_joint" type="revolute">
    <parent link="shoulder_link"/>
    <child link="upper_arm_link"/>
    <origin rpy="0.0 1.57079632679 0.0" xyz="0.0 0.12 0.0"/>
    <axis xyz="0 1 0"/>
    <limit effort="330.0" lower="-6.28318530718" upper="6.28318530718" velocity="3.14"/>
    <dynamics damping="0.0" friction="0.0"/>
  </joint>
  <link name="upper_arm_link">
    <visual>
      <geometry>
        <mesh filename="package://ur_e_description/meshes/ur3e/visual/upperarm.dae"/>
      </geometry>
      <material name="LightGrey">
        <color rgba="0.7 0.7 0.7 1.0"/>
      </material>
    </visual>
    <collision>
      <geometry>
        <mesh filename="package://ur_e_description/meshes/ur3e/collision/upperarm.stl"/>
      </geometry>
    </collision>
    <inertial>
      <mass value="3.42"/>
      <origin rpy="0 0 0" xyz="0.0 0.0 0.122"/>
      <inertia ixx="0.0217771262891" ixy="0.0" ixz="0.0" iyy="0.0217771262891" iyz="0.0" izz="0.00961875"/>
    </inertial>
  </link>
  <joint name="elbow_joint" type="revolute">
    <parent link="upper_arm_link"/>
    <child link="forearm_link"/>
    <origin rpy="0.0 0.0 0.0" xyz="0.0 -0.093 0.244"/>
    <axis xyz="0 1 0"/>
    <limit effort="150.0" lower="-6.28318530718" upper="6.28318530718" velocity="3.14"/>
    <dynamics damping="0.0" friction="0.0"/>
  </joint>
  <link name="forearm_link">
    <visual>
      <geometry>
        <mesh filename="package://ur_e_description/meshes/ur3e/visual/forearm.dae"/>
      </geometry>
      <material name="LightGrey">
        <color rgba="0.7 0.7 0.7 1.0"/>
      </material>
    </visual>
    <collision>
      <geometry>
        <mesh filename="package://ur_e_description/meshes/ur3e/collision/forearm.stl"/>
      </geometry>
    </collision>
    <inertial>
      <mass value="1.26"/>
      <origin rpy="0 0 0" xyz="0.0 0.0 0.1065"/>
      <inertia ixx="0.00653561738575" ixy="0.0" ixz="0.0" iyy="0.00653561738575" iyz="0.0" izz="0.00354375"/>
    </inertial>
  </link>
  <joint name="wrist_1_joint" type="revolute">
    <parent link="forearm_link"/>
    <child link="wrist_1_link"/>
    <origin rpy="0.0 1.57079632679 0.0" xyz="0.0 0.0 0.213"/>
    <axis xyz="0 1 0"/>
    <limit effort="54.0" lower="-6.28318530718" upper="6.28318530718" velocity="6.28"/>
    <dynamics damping="0.0" friction="0.0"/>
  </joint>
  <link name="wrist_1_link">
    <visual>
      <geometry>
        <mesh filename="package://ur_e_description/meshes/ur3e/visual/wrist1.dae"/>
      </geometry>
      <material name="LightGrey">
        <color rgba="0.7 0.7 0.7 1.0"/>
      </material>
    </visual>
    <collision>
      <geometry>
        <mesh filename="package://ur_e_description/meshes/ur3e/collision/wrist1.stl"/>
      </geometry>
    </collision>
    <inertial>
      <mass value="0.8"/>
      <origin rpy="0 0 0" xyz="0.0 0.0 0.0"/>
      <inertia ixx="0.002084999166" ixy="0.0" ixz="0.0" iyy="0.002084999166" iyz="0.0" izz="0.00225"/>
    </inertial>
  </link>
  <joint name="wrist_2_joint" type="revolute">
    <parent link="wrist_1_link"/>
    <child link="wrist_2_link"/>
    <origin rpy="0.0 0.0 0.0" xyz="0.0 0.104 0.0"/>
    <axis xyz="0 0 1"/>
    <limit effort="54.0" lower="-6.28318530718" upper="6.28318530718" velocity="6.28"/>
    <dynamics damping="0.0" friction="0.0"/>
  </joint>
  <link name="wrist_2_link">
    <visual>
      <geometry>
        <mesh filename="package://ur_e_description/meshes/ur3e/visual/wrist2.dae"/>
      </geometry>
      <material name="LightGrey">
        <color rgba="0.7 0.7 0.7 1.0"/>
      </material>
    </visual>
    <collision>
      <geometry>
        <mesh filename="package://ur_e_description/meshes/ur3e/collision/wrist2.stl"/>
      </geometry>
    </collision>
    <inertial>
      <mass value="0.8"/>
      <origin rpy="0 0 0" xyz="0.0 0.0 0.0"/>
      <inertia ixx="0.002084999166" ixy="0.0" ixz="0.0" iyy="0.002084999166" iyz="0.0" izz="0.00225"/>
    </inertial>
  </link>
  <joint name="wrist_3_joint" type="revolute">
    <parent link="wrist_2_link"/>
    <child link="wrist_3_link"/>
    <origin rpy="0.0 0.0 0.0" xyz="0.0 0.0 0.085"/>
    <axis xyz="0 1 0"/>
    <limit effort="54.0" lower="-6.28318530718" upper="6.28318530718" velocity="6.28"/>
    <dynamics damping="0.0" friction="0.0"/>
  </joint>
  <link name="wrist_3_link">
    <visual>
      <geometry>
        <mesh filename="package://ur_e_description/meshes/ur3e/visual/wrist3.dae"/>
      </geometry>
      <material name="LightGrey">
        <color rgba="0.7 0.7 0.7 1.0"/>
      </material>
    </visual>
    <collision>
      <geometry>
        <mesh filename="package://ur_e_description/meshes/ur3e/collision/wrist3.stl"/>
      </geometry>
    </collision>
    <inertial>
      <mass value="0.35"/>
      <origin rpy="0 0 0" xyz="0.0 0.0 0.0"/>
      <inertia ixx="0.000912187135125" ixy="0.0" ixz="0.0" iyy="0.000912187135125" iyz="0.0" izz="0.000984375"/>
    </inertial>
  </link>
  <joint name="ee_fixed_joint" type="fixed">
    <parent link="wrist_3_link"/>
    <child link="ee_link"/>
    <origin rpy="0.0 0.0 1.57079632679" xyz="0.0 0.092 0.0"/>
  </joint>
  <link name="ee_link">
    <collision>
      <geometry>
        <box size="0.01 0.01 0.01"/>
      </geometry>
      <origin rpy="0 0 0" xyz="-0.01 0 0"/>
    </collision>
  </link>
  <transmission name="shoulder_pan_trans">
    <type>transmission_interface/SimpleTransmission</type>
    <joint name="shoulder_pan_joint">
      <hardwareInterface>hardware_interface/PositionJointInterface</hardwareInterface>
    </joint>
    <actuator name="shoulder_pan_motor">
      <mechanicalReduction>1</mechanicalReduction>
    </actuator>
  </transmission>
  <transmission name="shoulder_lift_trans">
    <type>transmission_interface/SimpleTransmission</type>
    <joint name="shoulder_lift_joint">
      <hardwareInterface>hardware_interface/PositionJointInterface</hardwareInterface>
    </joint>
    <actuator name="shoulder_lift_motor">
      <mechanicalReduction>1</mechanicalReduction>
    </actuator>
  </transmission>
  <transmission name="elbow_trans">
    <type>transmission_interface/SimpleTransmission</type>
    <joint name="elbow_joint">
      <hardwareInterface>hardware_interface/PositionJointInterface</hardwareInterface>
    </joint>
    <actuator name="elbow_motor">
      <mechanicalReduction>1</mechanicalReduction>
    </actuator>
  </transmission>
  <transmission name="wrist_1_trans">
    <type>transmission_interface/SimpleTransmission</type>
    <joint name="wrist_1_joint">
      <hardwareInterface>hardware_interface/PositionJointInterface</hardwareInterface>
    </joint>
    <actuator name="wrist_1_motor">
      <mechanicalReduction>1</mechanicalReduction>
    </actuator>
  </transmission>
  <transmission name="wrist_2_trans">
    <type>transmission_interface/SimpleTransmission</type>
    <joint name="wrist_2_joint">
      <hardwareInterface>hardware_interface/PositionJointInterface</hardwareInterface>
    </joint>
    <actuator name="wrist_2_motor">
      <mechanicalReduction>1</mechanicalReduction>
    </actuator>
  </transmission>
  <transmission name="wrist_3_trans">
    <type>transmission_interface/SimpleTransmission</type>
    <joint name="wrist_3_joint">
      <hardwareInterface>hardware_interface/PositionJointInterface</hardwareInterface>
    </joint>
    <actuator name="wrist_3_motor">
      <mechanicalReduction>1</mechanicalReduction>
    </actuator>
  </transmission>
  <!-- <xacro:ur_arm_transmission prefix="${prefix}" joint_interface="VelocityJointInterface" /> -->
  <gazebo reference="shoulder_link">
    <selfCollide>true</selfCollide>
    <implicitSpringDamper>1</implicitSpringDamper>
  </gazebo>
  <gazebo reference="upper_arm_link">
    <selfCollide>true</selfCollide>
    <implicitSpringDamper>1</implicitSpringDamper>
  </gazebo>
  <gazebo reference="forearm_link">
    <selfCollide>true</selfCollide>
    <implicitSpringDamper>1</implicitSpringDamper>
  </gazebo>
  <gazebo reference="wrist_1_link">
    <selfCollide>true</selfCollide>
    <implicitSpringDamper>1</implicitSpringDamper>
  </gazebo>
  <gazebo reference="wrist_3_link">
    <selfCollide>true</selfCollide>
    <implicitSpringDamper>1</implicitSpringDamper>
  </gazebo>
  <gazebo reference="wrist_2_link">
    <selfCollide>true</selfCollide>
    <implicitSpringDamper>1</implicitSpringDamper>
  </gazebo>
  <gazebo reference="ee_link">
    <selfCollide>true</selfCollide>
    <implicitSpringDamper>1</implicitSpringDamper>
  </gazebo>
  <!-- ROS base_link to UR 'Base' Coordinates transform -->
  <link name="base"/>
  <joint name="base_link-base_fixed_joint" type="fixed">
    <!-- NOTE: this rotation is only needed as long as base_link itself is
                 not corrected wrt the real robot (ie: rotated over 180
                 degrees)
      -->
    <origin rpy="0 0 -3.14159265359" xyz="0 0 0"/>
    <parent link="base_link"/>
    <child link="base"/>
  </joint>
  <!-- Frame coincident with all-zeros TCP on UR controller -->
  <link name="tool0"/>
  <joint name="wrist_3_link-tool0_fixed_joint" type="fixed">
    <origin rpy="-1.57079632679 0 0" xyz="0 0.092 0"/>
    <parent link="wrist_3_link"/>
    <child link="tool0"/>
  </joint>
  <gazebo reference="wrist_3_link-tool0_fixed_joint">
    <disableFixedJointLumping>true</disableFixedJointLumping>
  </gazebo>
  <link name="world"/>
  <joint name="world_joint" type="fixed">
    <parent link="world"/>
    <child link="base_link"/>
    <origin rpy="0.0 0.0 0.0" xyz="0.0 0.0 0.0"/>
  </joint>
  <!--
  Author: Cristian Beltran
-->
  <!-- Robotiq Coupler -->
  <!--  + Height added by the coupler: 8mm -->
  <!--  + Reference frame: at the middle (4mm) -->
  <link name="robotiq_coupler">
    <visual>
      <geometry>
        <mesh filename="package://robotiq_description/meshes/robotiq_85_coupler.stl"/>
      </geometry>
      <material name="flat_black"/>
    </visual>
    <collision>
      <geometry>
        <mesh filename="package://robotiq_description/meshes/robotiq_85_coupler.stl"/>
      </geometry>
    </collision>
    <inertial>
      <origin rpy="0 0 0" xyz="2.073e-05   1.45286e-03  -1.1049e-03"/>
      <mass value="0.168"/>
      <inertia ixx="6.69695624e-05" ixy="5.21511788e-09" ixz="-2.74383009e-08" iyy="7.85088161e-05" iyz="5.41105193e-07" izz="1.41819717e-04"/>
    </inertial>
  </link>
  <joint name="robotiq_coupler_joint" type="fixed">
    <origin rpy="0 0 -1.57079632679" xyz="0 0 0.004"/>
    <parent link="tool0"/>
    <child link="robotiq_coupler"/>
  </joint>
  <gazebo reference="robotiq_coupler">
    <mu1>0.9</mu1>
    <mu2>0.9</mu2>
    <material>Gazebo/FlatBlack</material>
  </gazebo>
  <!-- Equivalent to the OpenRAVE manipulator denso_robotiq_hande_gripper -->
  <link name="ur3_robotiq_hande_gripper"/>
  <joint name="manipulator_dummy_joint" type="fixed">
    <origin rpy="0 0 0" xyz="0 0 0.1441"/>
    <parent link="robotiq_coupler"/>
    <child link="ur3_robotiq_hande_gripper"/>
  </joint>
  <joint name="robotiq_hande_base_joint" type="fixed">
    <parent link="robotiq_coupler"/>
    <child link="hand_e_link"/>
    <origin rpy="0 0 1.57079632679" xyz="0 0 0.004"/>
  </joint>
  <link name="hand_e_link">
    <inertial>
      <origin rpy="0 0 0" xyz="0 0 0.04607"/>
      <mass value="0.86387"/>
      <inertia ixx="1017560E-9" ixy="0" ixz="2235E-9" iyy="1028041E-9" iyz="0" izz="489810E-9"/>
    </inertial>
    <visual>
      <origin rpy="0 0 0" xyz="0 0 0"/>
      <geometry>
        <mesh filename="package://robotiq_description/meshes/hande/hand-e.dae" scale="1.0 1.0 1.0"/>
      </geometry>
      <material name="Dark">
        <color rgba=".1 0.1 0.1 1.0"/>
      </material>
    </visual>
    <collision>
      <origin rpy="0 0 0" xyz="0 0 0"/>
      <geometry>
        <mesh filename="package://robotiq_description/meshes/hande/hand-e.dae" scale="1.0 1.0 1.0"/>
      </geometry>
    </collision>
  </link>
  <link name="hande_left_finger">
    <inertial>
      <origin rpy="0 0 0" xyz="0.02262 -0.00759 0.00738"/>
      <mass value="0.03804"/>
      <inertia ixx="13567E-9" ixy="1849E-9" ixz="3622E-9" iyy="15784E-9" iyz="3616E-9" izz="7478E-9"/>
    </inertial>
    <visual>
      <origin rpy="0 0 0" xyz="0 0 0"/>
      <geometry>
        <mesh filename="package://robotiq_description/meshes/hande/finger_1.dae" scale="1.0 1.0 1.0"/>
      </geometry>
      <material name="DarkGray">
        <color rgba=".4 0.4 0.4 1.0"/>
      </material>
    </visual>
    <collision>
      <origin rpy="0 0 0" xyz="0 0 0"/>
      <geometry>
        <mesh filename="package://robotiq_description/meshes/hande/finger_1.dae" scale="1.0 1.0 1.0"/>
      </geometry>
    </collision>
  </link>
  <link name="hande_right_finger">
    <inertial>
      <origin rpy="0 0 0" xyz="-0.02262 0.00759 0.00738"/>
      <mass value="0.03804"/>
      <inertia ixx="13567E-9" ixy="1849E-9" ixz="-3622E-9" iyy="15784E-9" iyz="-3616E-9" izz="7478E-9"/>
    </inertial>
    <visual>
      <origin rpy="0 0 0" xyz="0 0 0"/>
      <geometry>
        <mesh filename="package://robotiq_description/meshes/hande/finger_2.dae" scale="1.0 1.0 1.0"/>
      </geometry>
      <material name="DarkGray">
        <color rgba=".4 0.4 0.4 1.0"/>
      </material>
    </visual>
    <collision>
      <origin rpy="0 0 0" xyz="0 0 0"/>
      <geometry>
        <mesh filename="package://robotiq_description/meshes/hande/finger_2.dae" scale="1.0 1.0 1.0"/>
      </geometry>
    </collision>
  </link>
  <gazebo reference="hand_e_link">
    <material>Gazebo/FlatBlack</material>
  </gazebo>
  <gazebo reference="hande_right_finger">
    <material>Gazebo/Grey</material>
  </gazebo>
  <gazebo reference="hande_left_finger">
    <material>Gazebo/Grey</material>
  </gazebo>
  <joint name="hande_left_finger_joint" type="prismatic">
    <origin rpy="0 0 0" xyz="0 0 0.099"/>
    <parent link="hand_e_link"/>
    <child link="hande_left_finger"/>
    <axis xyz="-1 0 0"/>
    <limit effort="130" lower="0" upper="0.025" velocity="0.15"/>
  </joint>
  <joint name="hande_right_finger_joint" type="prismatic">
    <origin rpy="0 0 0" xyz="0 0 0.099"/>
    <parent link="hand_e_link"/>
    <child link="hande_right_finger"/>
    <axis xyz="1 0 0"/>
    <limit effort="130" lower="0" upper="0.025" velocity="0.15"/>
    <mimic joint="hande_left_finger_joint" multiplier="1" offset="0"/>
  </joint>
  <!-- Improve grasping physics -->
  <gazebo reference="hande_left_finger">
    <kp>1000000.0</kp>
    <kd>1.0</kd>
    <mu1>1.0</mu1>
    <mu2>1.0</mu2>
    <minDepth>0.001</minDepth>
  </gazebo>
  <gazebo reference="hande_right_finger">
    <kp>1000000.0</kp>
    <kd>1.0</kd>
    <mu1>1.0</mu1>
    <mu2>1.0</mu2>
    <minDepth>0.001</minDepth>
  </gazebo>
  <!-- <transmission name="${prefix}hande_left_finger_trans">
      <type>transmission_interface/SimpleTransmission</type>
      <joint name="${prefix}hande_left_finger_joint">
        <hardwareInterface>hardware_interface/PositionJointInterface</hardwareInterface>
      </joint>
      <actuator name="${prefix}hande_left_finger_motor">
        <mechanicalReduction>1</mechanicalReduction>
      </actuator>
    </transmission> -->
  <transmission name="hande_right_finger_trans">
    <type>transmission_interface/SimpleTransmission</type>
    <joint name="hande_right_finger_joint">
      <hardwareInterface>hardware_interface/PositionJointInterface</hardwareInterface>
    </joint>
    <actuator name="hande_right_finger_motor">
      <mechanicalReduction>1</mechanicalReduction>
    </actuator>
  </transmission>
  <!-- Mimic joints -->
  <gazebo>
    <plugin filename="libgazebo_mimic_joint_plugin.so" name="mimic_robotiq_hande">
      <joint>hande_right_finger_joint</joint>
      <mimicJoint>hande_left_finger_joint</mimicJoint>
      <multiplier>1.0</multiplier>
      <offset>0.0</offset>
    </plugin>
  </gazebo>
  <!-- <link name="aruco_marker">
    <visual>
      <geometry>
        <box size="0.1 0.1 0.01"/>
      </geometry>
    </visual>
  </link>
  <joint name="aruco_dummy_joint" type="fixed">
    <origin rpy="0 1.57079632679 1.57079632679" xyz="0 0 0.20"/>
    <parent link="robotiq_coupler"/>
    <child link="aruco_marker"/>
  </joint> -->
  <!-- <gazebo reference="aruco_marker">
    <material>CB/Apriltag36_11_00000</material>
  </gazebo> -->
  <!-- Gazebo FT sensor plugin -->
  <gazebo reference="wrist_3_link-tool0_fixed_joint">
    <provideFeedback>true</provideFeedback>
  </gazebo>
  <gazebo>
    <plugin filename="libgazebo_ros_ft_sensor.so" name="ft_sensor">
      <updateRate>400.0</updateRate>
      <topicName>wrench</topicName>
      <gaussianNoise>0.0</gaussianNoise>
      <jointName>wrist_3_link-tool0_fixed_joint</jointName>
    </plugin>
  </gazebo>
  <gazebo>
    <gripper name="gazebo_gripper">
      <grasp_check>
        <attach_steps>2</attach_steps>
        <detach_steps>2</detach_steps>
        <min_contact_count>3</min_contact_count>
      </grasp_check>
      <gripper_link>hande_right_finger</gripper_link>
      <gripper_link>hande_left_finger</gripper_link>
      <palm_link>hand_e_link</palm_link>
    </gripper>
  </gazebo>
  <!-- Gazebo grasping plugin -->
</robot>
