<?xml version="1.0" encoding="utf-8"?>
<!-- =================================================================================== -->
<!-- |    This document was autogenerated by xacro from ur5e_gripper.xacro             | -->
<!-- |    EDITING THIS FILE BY HAND IS NOT RECOMMENDED                                 | -->
<!-- =================================================================================== -->
    <robot name="o2ac_base_scene"> <!-- This is the main file defining our robot arrangement and physical environment. -->
    <!-- measured from model -->
    <!-- link lengths used in model -->
    <!-- manually measured -->
        <link name="a_bot_base_link"> <visual>
            <origin rpy="0 0 3.14159265359" xyz="0 0 0"/>
            <geometry>
                <mesh filename="package://ur_e_description/meshes/ur5e/visual/base.dae"/>
            </geometry>
        </visual>
        <collision>
            <origin rpy="0 0 3.14159265359" xyz="0 0 0"/>
            <geometry>
                <mesh filename="package://ur_e_description/meshes/ur5e/collision/base.stl"/>
            </geometry>
        </collision>
        <inertial>
            <mass value="4.0"/>
            <origin rpy="0 0 0" xyz="0.0 0.0 0.0"/>
            <inertia ixx="0.00443333156" ixy="0.0" ixz="0.0" iyy="0.00443333156" iyz="0.0" izz="0.0072"/>
        </inertial>
    </link>
    <joint name="a_bot_shoulder_pan_joint" type="revolute">
        <parent link="a_bot_base_link"/>
        <child link="a_bot_shoulder_link"/>
        <origin rpy="0 0 3.14159265094" xyz="0 0 0.162655931584"/>
        <axis xyz="0 0 1"/>
        <limit effort="150.0" lower="-3.14159265359" upper="3.14159265359" velocity="3.14"/>
        <dynamics damping="0.0" friction="0.0"/>
    </joint>
    <link name="a_bot_shoulder_link">
        <visual>
            <origin rpy="0 0 3.14159265359" xyz="0 0 0"/>
            <geometry>
                <mesh filename="package://ur_e_description/meshes/ur5e/visual/shoulder.dae"/>
            </geometry>
        </visual>
        <collision>
            <origin rpy="0 0 3.14159265359" xyz="0 0 0"/>
            <geometry>
                <mesh filename="package://ur_e_description/meshes/ur5e/collision/shoulder.stl"/>
            </geometry>
        </collision>
        <inertial>
            <mass value="3.7"/>
            <origin rpy="0 0 0" xyz="0.0 0.0 0.0"/>
            <inertia ixx="0.010267495893" ixy="0.0" ixz="0.0" iyy="0.010267495893" iyz="0.0" izz="0.00666"/>
        </inertial>
    </link>
    <joint name="a_bot_shoulder_lift_joint" type="revolute">
        <parent link="a_bot_shoulder_link"/>
        <child link="a_bot_upper_arm_link"/>
        <origin rpy="1.56953512795 0 -2.84084164664e-07" xyz="0.000134779578882 0 0"/>
        <axis xyz="0 0 1"/>
        <limit effort="150.0" lower="-3.14159265359" upper="3.14159265359" velocity="3.14"/>
        <dynamics damping="0.0" friction="0.0"/>
    </joint>
    <link name="a_bot_upper_arm_link">
        <visual>
            <origin rpy="1.57079632679 0 -1.57079632679" xyz="0 0 0.138"/>
            <geometry>
                <mesh filename="package://ur_e_description/meshes/ur5e/visual/upperarm.dae"/>
            </geometry>
        </visual>
        <collision>
            <origin rpy="1.57079632679 0 -1.57079632679" xyz="0 0 0.138"/>
            <geometry>
                <mesh filename="package://ur_e_description/meshes/ur5e/collision/upperarm.stl"/>
            </geometry>
        </collision>
        <inertial>
            <mass value="8.393"/>
            <origin rpy="0 1.57079632679 0" xyz="-0.212633383271 0.0 0.138"/>
            <inertia ixx="0.138293379943" ixy="0.0" ixz="0.0" iyy="0.138293379943" iyz="0.0" izz="0.0236053125"/>
        </inertial>
    </link>
    <joint name="a_bot_elbow_joint" type="revolute">
        <parent link="a_bot_upper_arm_link"/>
        <child link="a_bot_forearm_link"/>
        <origin rpy="0.000119395911412 0.00163456023303 5.12790813273e-07" xyz="-0.425266766542 0 0"/>
        <axis xyz="0 0 1"/>
        <limit effort="150.0" lower="0.0" upper="3.14159265359" velocity="3.14"/>
        <dynamics damping="0.0" friction="0.0"/>
    </joint>
    <link name="a_bot_forearm_link">
        <visual>
            <origin rpy="1.57079632679 0 -1.57079632679" xyz="0 0 0.007"/>
            <geometry>
                <mesh filename="package://ur_e_description/meshes/ur5e/visual/forearm.dae"/>
            </geometry>
        </visual>
        <collision>
            <origin rpy="1.57079632679 0 -1.57079632679" xyz="0 0 0.007"/>
            <geometry>
                <mesh filename="package://ur_e_description/meshes/ur5e/collision/forearm.stl"/>
            </geometry>
        </collision>
        <inertial>
            <mass value="2.275"/>
            <origin rpy="0 1.57079632679 0" xyz="-0.212633383271 0.0 0.007"/>
            <inertia ixx="0.0324280715332" ixy="0.0" ixz="0.0" iyy="0.0324280715332" iyz="0.0" izz="0.0063984375"/>
        </inertial>
    </link>
    <joint name="a_bot_wrist_1_joint" type="revolute">
        <parent link="a_bot_forearm_link"/>
        <child link="a_bot_wrist_1_link"/>
        <origin rpy="0.00240514304011 -0.00147917631702 -3.8502770334e-07" xyz="-0.392650273076 -0.000321358811681 0.133612923084"/>
        <axis xyz="0 0 1"/>
        <limit effort="28.0" lower="-4.71238898038" upper="3.14159265359" velocity="6.28"/>
        <dynamics damping="0.0" friction="0.0"/>
    </joint>
    <link name="a_bot_wrist_1_link">
        <visual>
            <origin rpy="1.57079632679 0 0" xyz="0 0 -0.127"/>
            <geometry>
                <mesh filename="package://ur_e_description/meshes/ur5e/visual/wrist1.dae"/>
            </geometry>
        </visual>
        <collision>
            <origin rpy="1.57079632679 0 0" xyz="0 0 -0.127"/>
            <geometry>
                <mesh filename="package://ur_e_description/meshes/ur5e/collision/wrist1.stl"/>
            </geometry>
        </collision>
        <inertial>
            <mass value="1.219"/>
            <origin rpy="0 0 0" xyz="0.0 0.0 0.0"/>
            <inertia ixx="0.00272444225937" ixy="0.0" ixz="0.0" iyy="0.00272444225937" iyz="0.0" izz="0.0034284375"/>
        </inertial>
    </link>
    <joint name="a_bot_wrist_2_joint" type="revolute">
        <parent link="a_bot_wrist_1_link"/>
        <child link="a_bot_wrist_2_link"/>
        <origin rpy="1.56963272494 0 9.63633041889e-08" xyz="8.31335451575e-05 -0.0997235522137 0.000116038562953"/>
        <axis xyz="0 0 1"/>
        <limit effort="28.0" lower="-4.71238898038" upper="4.71238898038" velocity="6.28"/>
        <dynamics damping="0.0" friction="0.0"/>
    </joint>
    <link name="a_bot_wrist_2_link">
        <visual>
            <origin rpy="0 0 0" xyz="0 0 -0.0997"/>
            <geometry>
                <mesh filename="package://ur_e_description/meshes/ur5e/visual/wrist2.dae"/>
            </geometry>
        </visual>
        <collision>
            <origin rpy="0 0 0" xyz="0 0 -0.0997"/>
            <geometry>
                <mesh filename="package://ur_e_description/meshes/ur5e/collision/wrist2.stl"/>
            </geometry>
        </collision>
        <inertial>
            <mass value="1.219"/>
            <origin rpy="0 0 0" xyz="0.0 0.0 0.0"/>
            <inertia ixx="0.00272116872319" ixy="0.0" ixz="0.0" iyy="0.00272116872319" iyz="0.0" izz="0.0034284375"/>
        </inertial>
    </link>
    <joint name="a_bot_wrist_3_joint" type="revolute">
        <parent link="a_bot_wrist_2_link"/>
        <child link="a_bot_wrist_3_link"/>
        <origin rpy="1.57226982462 3.14159265359 3.14159261802" xyz="8.83928394576e-05 0.0995618487303 0.000146704273679"/>
        <axis xyz="0 0 1"/>
        <limit effort="28.0" lower="-6.28318530718" upper="6.28318530718" velocity="6.28"/>
        <dynamics damping="0.0" friction="0.0"/>
    </joint>
    <link name="a_bot_wrist_3_link">
        <visual>
            <origin rpy="1.57079632679 0 0" xyz="0 0 -0.0989"/>
            <geometry>
                <mesh filename="package://ur_e_description/meshes/ur5e/visual/wrist3.dae"/>
            </geometry>
        </visual>
        <collision>
            <origin rpy="1.57079632679 0 0" xyz="0 0 -0.0989"/>
            <geometry>
                <mesh filename="package://ur_e_description/meshes/ur5e/collision/wrist3.stl"/>
            </geometry>
        </collision>
        <inertial>
            <mass value="0.1879"/>
            <origin rpy="0 0 0" xyz="0.0 0.0 -0.025"/>
            <inertia ixx="0.000134270154625" ixy="0.0" ixz="0.0" iyy="0.000134270154625" iyz="0.0" izz="0.00019024875"/>
        </inertial>
    </link>
    <joint name="a_bot_ee_fixed_joint" type="fixed">
        <parent link="a_bot_wrist_3_link"/>
        <child link="a_bot_ee_link"/>
        <origin rpy="0.0 -1.57079632679 1.57079632679" xyz="0.0 0.0 0.0"/>
    </joint>
    <link name="a_bot_ee_link">
        <collision>
            <geometry>
                <box size="0.01 0.01 0.01"/>
            </geometry>
            <origin rpy="0 0 0" xyz="-0.01 0 0"/>
        </collision>
    </link>
    <!-- ROS base_link to UR 'Base' Coordinates transform -->
    <link name="a_bot_base"/>
    <joint
        name="a_bot_base_link-base_fixed_joint" type="fixed">
        <!-- NOTE: this rotation is only needed as long as base_link itself is
                         not corrected wrt the real robot (ie: rotated over 180
                         degrees)
              -->
        <origin rpy="0 0 -3.14159265359" xyz="0 0 0"/>
        <parent link="a_bot_base_link"/>
        <child link="a_bot_base"/>
    </joint>
    <!-- Frame coincident with all-zeros TCP on UR controller -->
    <link name="a_bot_tool0"/>
    <joint name="a_bot_wrist_3_link-tool0_fixed_joint" type="fixed">
        <origin rpy="0 0 0" xyz="0 0 0"/>
        <parent link="a_bot_wrist_3_link"/>
        <child link="a_bot_tool0"/>
    </joint>
    <joint name="a_bot_robotiq_140_base_joint" type="fixed">
        <parent link="a_bot_tool0"/>
        <child link="a_bot_robotiq_140_base_link"/>
        <origin rpy="0.0 0.0 0.0" xyz="0 0 0"/>
    </joint>
    <link name="a_bot_robotiq_140_base_link"/>
    <joint name="a_bot_robotiq_arg2f_base_joint" type="fixed">
        <parent link="a_bot_robotiq_140_base_link"/>
        <child link="a_bot_robotiq_arg2f_base_link"/>
        <origin rpy="3.14159265359 -1.57079632679 0" xyz="0 0 0"/>
    </joint>
    <link name="a_bot_robotiq_arg2f_base_link">
        <inertial>
            <origin rpy="0 0 0" xyz="8.625E-08 -4.6583E-06 0.03145"/>
            <mass value="0.22652"/>
            <inertia ixx="0.00020005" ixy="-4.2442E-10" ixz="-2.9069E-10" iyy="0.00017832" iyz="-3.4402E-08" izz="0.00013478"/>
        </inertial>
        <visual>
            <origin rpy="0 0 0" xyz="0 0 0"/>
            <geometry>
                <mesh filename="package://robotiq_description/meshes/visual/robotiq_arg2f_base_link.stl"/>
            </geometry>
        </visual>
        <collision>
            <origin rpy="0 0 0" xyz="0 0 0"/>
            <geometry>
                <mesh filename="package://robotiq_description/meshes/collision/robotiq_arg2f_base_link.stl"/>
            </geometry>
        </collision>
    </link>
    <link name="a_bot_left_outer_knuckle">
        <inertial>
            <origin rpy="0 0 0" xyz="-0.000200000000003065 0.0199435877845359 0.0292245259211331"/>
            <mass value="0.00853198276973456"/>
            <inertia ixx="2.89328108496468E-06" ixy="-1.57935047237397E-19" ixz="-1.93980378593255E-19" iyy="1.86719750325683E-06" iyz="-1.21858577871576E-06" izz="1.21905238907251E-06"/>
        </inertial>
        <visual>
            <origin rpy="0 0 0" xyz="0 0 0"/>
            <geometry>
                <mesh filename="package://robotiq_description/meshes/visual/robotiq_arg2f_140_outer_knuckle.stl"/>
            </geometry>
        </visual>
        <collision>
            <origin rpy="0 0 0" xyz="0 0 0"/>
            <geometry>
                <mesh filename="package://robotiq_description/meshes/collision/robotiq_arg2f_140_outer_knuckle.stl"/>
            </geometry>
        </collision>
    </link>
    <link name="a_bot_left_outer_finger">
        <inertial>
            <origin rpy="0 0 0" xyz="0.00030115855001899 0.0373907951953854 -0.0208027427000385"/>
            <mass value="0.022614240507152"/>
            <inertia ixx="1.52518312458174E-05" ixy="9.76583423954399E-10" ixz="-5.43838577022588E-10" iyy="6.17694243867776E-06" iyz="6.78636130740228E-06" izz="1.16494917907219E-05"/>
        </inertial>
        <visual>
            <origin rpy="0 0 0" xyz="0 0 0"/>
            <geometry>
                <mesh filename="package://robotiq_description/meshes/visual/robotiq_arg2f_140_outer_finger.stl"/>
            </geometry>
        </visual>
        <collision>
            <origin rpy="0 0 0" xyz="0 0 0"/>
            <geometry>
                <mesh filename="package://robotiq_description/meshes/collision/robotiq_arg2f_140_outer_finger.stl"/>
            </geometry>
        </collision>
    </link>
    <link name="a_bot_left_inner_finger">
        <inertial>
            <origin rpy="0 0 0" xyz="0.000299999999999317 0.0160078233491243 -0.0136945669206257"/>
            <mass value="0.0104003125914103"/>
            <inertia ixx="2.71909453810972E-06" ixy="1.35402465472579E-21" ixz="-7.1817349065269E-22" iyy="7.69100314106116E-07" iyz="6.74715432769696E-07" izz="2.30315190420171E-06"/>
        </inertial>
        <visual>
            <origin rpy="0 0 0" xyz="0 0 0"/>
            <geometry>
                <mesh filename="package://robotiq_description/meshes/visual/robotiq_arg2f_140_inner_finger.stl"/>
            </geometry>
        </visual>
        <collision>
            <origin rpy="0 0 0" xyz="0 0 0"/>
            <geometry>
                <mesh filename="package://robotiq_description/meshes/collision/robotiq_arg2f_140_inner_finger.stl"/>
            </geometry>
        </collision>
    </link>
    <link name="a_bot_left_inner_finger_pad">
        <visual>
            <origin rpy="0 0 0" xyz="0 0 0"/>
            <geometry>
                <box size="0.027 0.065 0.0075"/>
            </geometry>
        </visual>
        <collision>
            <origin rpy="0 0 0" xyz="0 0 0"/>
            <geometry>
                <box size="0.03 0.07 0.0075"/>
            </geometry>
        </collision>
    </link>
    <link name="a_bot_left_inner_knuckle">
        <inertial>
            <origin rpy="0 0 0" xyz="0.000123011831763771 0.0507850843201817 0.00103968640075166"/>
            <mass value="0.0271177346495152"/>
            <inertia ixx="2.61910379223783E-05" ixy="-2.43616858946494E-07" ixz="-6.37789906117123E-09" iyy="2.8270243746167E-06" iyz="-5.37200748039765E-07" izz="2.83695868220296E-05"/>
        </inertial>
        <visual>
            <origin rpy="0 0 0" xyz="0 0 0"/>
            <geometry>
                <mesh filename="package://robotiq_description/meshes/visual/robotiq_arg2f_140_inner_knuckle.stl"/>
            </geometry>
        </visual>
        <collision>
            <origin rpy="0 0 0" xyz="0 0 0"/>
            <geometry>
                <mesh filename="package://robotiq_description/meshes/collision/robotiq_arg2f_140_inner_knuckle.stl"/>
            </geometry>
        </collision>
    </link>
    <link name="a_bot_right_outer_knuckle">
        <inertial>
            <origin rpy="0 0 0" xyz="-0.000200000000003065 0.0199435877845359 0.0292245259211331"/>
            <mass value="0.00853198276973456"/>
            <inertia ixx="2.89328108496468E-06" ixy="-1.57935047237397E-19" ixz="-1.93980378593255E-19" iyy="1.86719750325683E-06" iyz="-1.21858577871576E-06" izz="1.21905238907251E-06"/>
        </inertial>
        <visual>
            <origin rpy="0 0 0" xyz="0 0 0"/>
            <geometry>
                <mesh filename="package://robotiq_description/meshes/visual/robotiq_arg2f_140_outer_knuckle.stl"/>
            </geometry>
        </visual>
        <collision>
            <origin rpy="0 0 0" xyz="0 0 0"/>
            <geometry>
                <mesh filename="package://robotiq_description/meshes/collision/robotiq_arg2f_140_outer_knuckle.stl"/>
            </geometry>
        </collision>
    </link>
    <link name="a_bot_right_outer_finger">
        <inertial>
            <origin rpy="0 0 0" xyz="0.00030115855001899 0.0373907951953854 -0.0208027427000385"/>
            <mass value="0.022614240507152"/>
            <inertia ixx="1.52518312458174E-05" ixy="9.76583423954399E-10" ixz="-5.43838577022588E-10" iyy="6.17694243867776E-06" iyz="6.78636130740228E-06" izz="1.16494917907219E-05"/>
        </inertial>
        <visual>
            <origin rpy="0 0 0" xyz="0 0 0"/>
            <geometry>
                <mesh filename="package://robotiq_description/meshes/visual/robotiq_arg2f_140_outer_finger.stl"/>
            </geometry>
        </visual>
        <collision>
            <origin rpy="0 0 0" xyz="0 0 0"/>
            <geometry>
                <mesh filename="package://robotiq_description/meshes/collision/robotiq_arg2f_140_outer_finger.stl"/>
            </geometry>
        </collision>
    </link>
    <link name="a_bot_right_inner_finger">
        <inertial>
            <origin rpy="0 0 0" xyz="0.000299999999999317 0.0160078233491243 -0.0136945669206257"/>
            <mass value="0.0104003125914103"/>
            <inertia ixx="2.71909453810972E-06" ixy="1.35402465472579E-21" ixz="-7.1817349065269E-22" iyy="7.69100314106116E-07" iyz="6.74715432769696E-07" izz="2.30315190420171E-06"/>
        </inertial>
        <visual>
            <origin rpy="0 0 0" xyz="0 0 0"/>
            <geometry>
                <mesh filename="package://robotiq_description/meshes/visual/robotiq_arg2f_140_inner_finger.stl"/>
            </geometry>
        </visual>
        <collision>
            <origin rpy="0 0 0" xyz="0 0 0"/>
            <geometry>
                <mesh filename="package://robotiq_description/meshes/collision/robotiq_arg2f_140_inner_finger.stl"/>
            </geometry>
        </collision>
    </link>
    <link name="a_bot_right_inner_finger_pad">
        <visual>
            <origin rpy="0 0 0" xyz="0 0 0"/>
            <geometry>
                <box size="0.027 0.065 0.0075"/>
            </geometry>
        </visual>
        <collision>
            <origin rpy="0 0 0" xyz="0 0 0"/>
            <geometry>
                <box size="0.03 0.07 0.0075"/>
            </geometry>
        </collision>
    </link>
    <link name="a_bot_right_inner_knuckle">
        <inertial>
            <origin rpy="0 0 0" xyz="0.000123011831763771 0.0507850843201817 0.00103968640075166"/>
            <mass value="0.0271177346495152"/>
            <inertia ixx="2.61910379223783E-05" ixy="-2.43616858946494E-07" ixz="-6.37789906117123E-09" iyy="2.8270243746167E-06" iyz="-5.37200748039765E-07" izz="2.83695868220296E-05"/>
        </inertial>
        <visual>
            <origin rpy="0 0 0" xyz="0 0 0"/>
            <geometry>
                <mesh filename="package://robotiq_description/meshes/visual/robotiq_arg2f_140_inner_knuckle.stl"/>
            </geometry>
        </visual>
        <collision>
            <origin rpy="0 0 0" xyz="0 0 0"/>
            <geometry>
                <mesh filename="package://robotiq_description/meshes/collision/robotiq_arg2f_140_inner_knuckle.stl"/>
            </geometry>
        </collision>
    </link>
    <joint name="a_bot_finger_joint" type="revolute">
        <origin rpy="2.29579632679 0 0" xyz="0 -0.030601 0.054905"/>
        <parent link="a_bot_robotiq_arg2f_base_link"/>
        <child link="a_bot_left_outer_knuckle"/>
        <axis xyz="-1 0 0"/>
        <limit effort="1000" lower="0" upper="0.7" velocity="2.0"/>
    </joint>
    <joint name="a_bot_left_outer_finger_joint" type="fixed">
        <origin rpy="0 0 0" xyz="0 0.01821998610742 0.0260018192872234"/>
        <parent link="a_bot_left_outer_knuckle"/>
        <child link="a_bot_left_outer_finger"/>
        <axis xyz="1 0 0"/>
    </joint>
    <joint name="a_bot_left_inner_knuckle_joint" type="revolute">
        <origin rpy="2.29579632679 0 0.0" xyz="0 -0.0127 0.06142"/>
        <parent link="a_bot_robotiq_arg2f_base_link"/>
        <child link="a_bot_left_inner_knuckle"/>
        <axis xyz="1 0 0"/>
        <limit effort="1000" lower="-0.8757" upper="0.8757" velocity="2.0"/>
        <mimic joint="a_bot_finger_joint" multiplier="-1" offset="0"/>
    </joint>
    <joint name="a_bot_left_inner_finger_joint" type="revolute">
        <origin rpy="-0.725 0 0" xyz="0 0.0817554015893473 -0.0282203446692936"/>
        <parent link="a_bot_left_outer_finger"/>
        <child link="a_bot_left_inner_finger"/>
        <axis xyz="1 0 0"/>
        <limit effort="1000" lower="-0.8757" upper="0.8757" velocity="2.0"/>
        <mimic joint="a_bot_finger_joint" multiplier="1" offset="0"/>
    </joint>
    <joint name="a_bot_left_inner_finger_pad_joint" type="fixed">
        <origin rpy="0 0 0" xyz="0 0.0457554015893473 -0.0272203446692936"/>
        <parent link="a_bot_left_inner_finger"/>
        <child link="a_bot_left_inner_finger_pad"/>
        <axis xyz="0 0 1"/>
    </joint>
    <joint name="a_bot_right_outer_knuckle_joint" type="revolute">
        <origin rpy="2.29579632679 0 3.14159265359" xyz="0 0.030601 0.054905"/>
        <parent link="a_bot_robotiq_arg2f_base_link"/>
        <child link="a_bot_right_outer_knuckle"/>
        <axis xyz="1 0 0"/>
        <limit effort="1000" lower="-0.725" upper="0.725" velocity="2.0"/>
        <mimic joint="a_bot_finger_joint" multiplier="-1" offset="0"/>
    </joint>
    <joint name="a_bot_right_outer_finger_joint" type="fixed">
        <origin rpy="0 0 0" xyz="0 0.01821998610742 0.0260018192872234"/>
        <parent link="a_bot_right_outer_knuckle"/>
        <child link="a_bot_right_outer_finger"/>
        <axis xyz="1 0 0"/>
    </joint>
    <joint name="a_bot_right_inner_knuckle_joint" type="revolute">
        <origin rpy="2.29579632679 0 -3.14159265359" xyz="0 0.0127 0.06142"/>
        <parent link="a_bot_robotiq_arg2f_base_link"/>
        <child link="a_bot_right_inner_knuckle"/>
        <axis xyz="1 0 0"/>
        <limit effort="1000" lower="-0.8757" upper="0.8757" velocity="2.0"/>
        <mimic joint="a_bot_finger_joint" multiplier="-1" offset="0"/>
    </joint>
    <joint name="a_bot_right_inner_finger_joint" type="revolute">
        <origin rpy="-0.725 0 0" xyz="0 0.0817554015893473 -0.0282203446692936"/>
        <parent link="a_bot_right_outer_finger"/>
        <child link="a_bot_right_inner_finger"/>
        <axis xyz="1 0 0"/>
        <limit effort="1000" lower="-0.8757" upper="0.8757" velocity="2.0"/>
        <mimic joint="a_bot_finger_joint" multiplier="1" offset="0"/>
    </joint>
    <joint name="a_bot_right_inner_finger_pad_joint" type="fixed">
        <origin rpy="0 0 0" xyz="0 0.0457554015893473 -0.0272203446692936"/>
        <parent link="a_bot_right_inner_finger"/>
        <child link="a_bot_right_inner_finger_pad"/>
        <axis xyz="0 0 1"/>
    </joint>
    <!-- Mimic joints -->
    <link name="a_bot_cam_mount">
        <inertial>
            <origin rpy="3.14159265359 0 1.57079632679" xyz="0 0 0.0"/>
            <mass value="1.0"/>
            <inertia ixx="1.0" ixy="0" ixz="0" iyy="1.0" iyz="0" izz="1.0"/>
        </inertial>
        <visual>
            <origin rpy="3.14159265359 0 1.57079632679" xyz="0 0 0.0"/>
            <geometry>
                <mesh filename="package://o2ac_scene_description/meshes/sr305_mount.stl" scale=".001 .001 .001"/>
            </geometry>
        </visual>
        <collision>
            <origin rpy="0 0 0" xyz="-.01 0.0 .035"/>
            <geometry>
                <box size=".03 .15 .08"/>
            </geometry>
        </collision>
    </link>
    <joint name="a_bot_cam_mount_joint" type="fixed">
        <parent link="a_bot_robotiq_140_base_link"/>
        <child link="a_bot_cam_mount"/>
        <origin rpy="0 0 0" xyz="0.035 0.0 0.025"/>
    </joint>
    <!-- A collision box to represent the USB 3.1 cable connectors on the side of the cameras -->
    <link name="a_bot_cam_cables_link">
        <inertial>
            <origin rpy="0 0 0" xyz="0 0 0.0"/>
            <mass value="0.1"/>
            <inertia ixx="1.0" ixy="0" ixz="0" iyy="1.0" iyz="0" izz="1.0"/>
        </inertial>
        <visual>
            <origin rpy="0 0 0" xyz="0 0 0"/>
            <geometry>
                <box size=".03 .03 .055"/>
            </geometry>
        </visual>
        <collision>
            <origin rpy="0 0 0" xyz="0 0 0"/>
            <geometry>
                <box size=".03 .03 .055"/>
            </geometry>
        </collision>
    </link>
    <joint name="a_bot_cam_cables_joint" type="fixed">
        <parent link="a_bot_robotiq_140_base_link"/>
        <child link="a_bot_cam_cables_link"/>
        <origin rpy="0 0 0" xyz=".034 -.085 0.07"/>
    </joint>
    <link name="a_bot_inside_cam_link"/>
    <joint name="a_bot_inside_cam_joint" type="fixed">
        <parent link="a_bot_robotiq_140_base_link"/>
        <child link="a_bot_inside_cam_link"/>
        <origin rpy="0 0.349065850399 0" xyz="0.026 0 0.0595"/>
    </joint>
    <!-- Left sensor (looking from front):  -7.54 mm, 0, -3.721 mm -->
    <!-- Right sensor (RGB?)(looking from front): 16.492 mm, 0, -3.721 mm -->
    <!-- 24.033 mm distance between the camera centers, apparently -->
    <!-- camera mount to origin: 4mm; cameras to origin: 3.721 mm. = 7.721 mm offset? -->
    <!-- I forgot which conventions exist for "camera_joint" and "camera_link_joint" so I hesitate to delete one. -->
        <joint name="a_bot_inside_camera_joint" type="fixed"> <origin rpy="0 0 0" xyz="0 0 0"/>
        <parent link="a_bot_inside_cam_link"/>
        <child link="a_bot_inside_camera_connector_link"/>
    </joint>
    <link name="a_bot_inside_camera_connector_link"/>
    <joint name="a_bot_inside_camera_link_joint" type="fixed">
        <origin rpy="0 0 0" xyz="0 0 0"/>
        <parent link="a_bot_inside_camera_connector_link"/>
        <child link="a_bot_inside_camera_link"/>
    </joint>
    <link name="a_bot_inside_camera_link">
        <visual>
            <origin rpy="1.57079632679 0 1.57079632679" xyz="0 -0.0 0"/>
            <geometry>
                <mesh filename="package://o2ac_scene_description/meshes/sr305_simplified_body.stl" scale=".001 .001 .001"/>
            </geometry>
        </visual>
        <collision>
            <origin rpy="0 0 0" xyz="0.006 -0.0 0"/>
            <geometry>
                <box size="0.012 0.14 0.023"/>
            </geometry>
        </collision>
        <inertial>
            <!-- The following are not reliable values, and should not be used for modeling -->
            <mass value="0.564"/>
            <origin xyz="0 0 0"/>
            <inertia ixx="0.003881243" ixy="0.0" ixz="0.0" iyy="0.000498940" iyz="0.0" izz="0.003879257"/>
        </inertial>
    </link>
    <!-- camera depth joints and links -->
    <joint name="a_bot_inside_camera_depth_joint" type="fixed">
        <origin rpy="0 0 0" xyz=".003721 0 0"/>
        <parent link="a_bot_inside_camera_link"/>
        <child link="a_bot_inside_camera_depth_frame"/>
    </joint>
    <link name="a_bot_inside_camera_depth_frame"/>
    <joint name="a_bot_inside_camera_depth_optical_joint" type="fixed">
        <origin rpy="-1.57079632679 0 -1.57079632679" xyz="0 0 0"/>
        <parent link="a_bot_inside_camera_depth_frame"/>
        <child link="a_bot_inside_camera_depth_optical_frame"/>
    </joint>
    <link
    name="a_bot_inside_camera_depth_optical_frame"/>
    <!-- camera left IR joints and links -->
    <joint name="a_bot_inside_camera_left_ir_joint" type="fixed">
        <origin rpy="0 0 0" xyz="0 0.0 0"/>
        <parent link="a_bot_inside_camera_depth_frame"/>
        <child link="a_bot_inside_camera_left_ir_frame"/>
    </joint>
    <link name="a_bot_inside_camera_left_ir_frame"/>
    <joint name="a_bot_inside_camera_left_ir_optical_joint" type="fixed">
        <origin rpy="-1.57079632679 0 -1.57079632679" xyz="0 0 0"/>
        <parent link="a_bot_inside_camera_left_ir_frame"/>
        <child link="a_bot_inside_camera_left_ir_optical_frame"/>
    </joint>
    <link
    name="a_bot_inside_camera_left_ir_optical_frame"/>
    <!-- camera right IR joints and links -->
    <joint name="a_bot_inside_camera_right_ir_joint" type="fixed">
        <origin rpy="0 0 0" xyz="0 0.04 0"/>
        <parent link="a_bot_inside_camera_depth_frame"/>
        <child link="a_bot_inside_camera_right_ir_frame"/>
    </joint>
    <link name="a_bot_inside_camera_right_ir_frame"/>
    <joint name="a_bot_inside_camera_right_ir_optical_joint" type="fixed">
        <origin rpy="-1.57079632679 0 -1.57079632679" xyz="0 0 0"/>
        <parent link="a_bot_inside_camera_right_ir_frame"/>
        <child link="a_bot_inside_camera_right_ir_optical_frame"/>
    </joint>
    <link
    name="a_bot_inside_camera_right_ir_optical_frame"/>
    <!-- camera color joints and links -->
    <joint name="a_bot_inside_camera_color_joint" type="fixed">
        <origin rpy="0 0 0" xyz="0 0.015 0"/>
        <parent link="a_bot_inside_camera_depth_frame"/>
        <child link="a_bot_inside_camera_color_frame"/>
    </joint>
    <link name="a_bot_inside_camera_color_frame"/>
    <joint name="a_bot_inside_camera_color_optical_joint" type="fixed">
        <origin rpy="-1.57079632679 0 -1.57079632679" xyz="0 0 0"/>
        <parent link="a_bot_inside_camera_color_frame"/>
        <child link="a_bot_inside_camera_color_optical_frame"/>
    </joint>
    <link name="a_bot_inside_camera_color_optical_frame"/>
    <link name="a_bot_outside_cam_link"/>
    <joint name="a_bot_outside_cam_joint" type="fixed">
        <parent link="a_bot_robotiq_140_base_link"/>
        <child link="a_bot_outside_cam_link"/>
        <origin rpy="0 -0.261799387799 0" xyz="0.026 0 0.0835"/>
    </joint>
    <!-- Left sensor (looking from front):  -7.54 mm, 0, -3.721 mm -->
    <!-- Right sensor (RGB?)(looking from front): 16.492 mm, 0, -3.721 mm -->
    <!-- 24.033 mm distance between the camera centers, apparently -->
    <!-- camera mount to origin: 4mm; cameras to origin: 3.721 mm. = 7.721 mm offset? -->
    <!-- I forgot which conventions exist for "camera_joint" and "camera_link_joint" so I hesitate to delete one. -->
        <joint name="a_bot_outside_camera_joint" type="fixed"> <origin rpy="0 0 0" xyz="0 0 0"/>
        <parent link="a_bot_outside_cam_link"/>
        <child link="a_bot_outside_camera_connector_link"/>
    </joint>
    <link name="a_bot_outside_camera_connector_link"/>
    <joint name="a_bot_outside_camera_link_joint" type="fixed">
        <origin rpy="0 0 0" xyz="0 0 0"/>
        <parent link="a_bot_outside_camera_connector_link"/>
        <child link="a_bot_outside_camera_link"/>
    </joint>
    <link name="a_bot_outside_camera_link">
        <visual>
            <origin rpy="1.57079632679 0 1.57079632679" xyz="0 -0.0 0"/>
            <geometry>
                <mesh filename="package://o2ac_scene_description/meshes/sr305_simplified_body.stl" scale=".001 .001 .001"/>
            </geometry>
        </visual>
        <collision>
            <origin rpy="0 0 0" xyz="0.006 -0.0 0"/>
            <geometry>
                <box size="0.012 0.14 0.023"/>
            </geometry>
        </collision>
        <inertial>
            <!-- The following are not reliable values, and should not be used for modeling -->
            <mass value="0.564"/>
            <origin xyz="0 0 0"/>
            <inertia ixx="0.003881243" ixy="0.0" ixz="0.0" iyy="0.000498940" iyz="0.0" izz="0.003879257"/>
        </inertial>
    </link>
    <!-- camera depth joints and links -->
    <joint name="a_bot_outside_camera_depth_joint" type="fixed">
        <origin rpy="0 0 0" xyz=".003721 0 0"/>
        <parent link="a_bot_outside_camera_link"/>
        <child link="a_bot_outside_camera_depth_frame"/>
    </joint>
    <link name="a_bot_outside_camera_depth_frame"/>
    <joint name="a_bot_outside_camera_depth_optical_joint" type="fixed">
        <origin rpy="-1.57079632679 0 -1.57079632679" xyz="0 0 0"/>
        <parent link="a_bot_outside_camera_depth_frame"/>
        <child link="a_bot_outside_camera_depth_optical_frame"/>
    </joint>
    <link
    name="a_bot_outside_camera_depth_optical_frame"/>
    <!-- camera left IR joints and links -->
    <joint name="a_bot_outside_camera_left_ir_joint" type="fixed">
        <origin rpy="0 0 0" xyz="0 0.0 0"/>
        <parent link="a_bot_outside_camera_depth_frame"/>
        <child link="a_bot_outside_camera_left_ir_frame"/>
    </joint>
    <link name="a_bot_outside_camera_left_ir_frame"/>
    <joint name="a_bot_outside_camera_left_ir_optical_joint" type="fixed">
        <origin rpy="-1.57079632679 0 -1.57079632679" xyz="0 0 0"/>
        <parent link="a_bot_outside_camera_left_ir_frame"/>
        <child link="a_bot_outside_camera_left_ir_optical_frame"/>
    </joint>
    <link
    name="a_bot_outside_camera_left_ir_optical_frame"/>
    <!-- camera right IR joints and links -->
    <joint name="a_bot_outside_camera_right_ir_joint" type="fixed">
        <origin rpy="0 0 0" xyz="0 0.04 0"/>
        <parent link="a_bot_outside_camera_depth_frame"/>
        <child link="a_bot_outside_camera_right_ir_frame"/>
    </joint>
    <link name="a_bot_outside_camera_right_ir_frame"/>
    <joint name="a_bot_outside_camera_right_ir_optical_joint" type="fixed">
        <origin rpy="-1.57079632679 0 -1.57079632679" xyz="0 0 0"/>
        <parent link="a_bot_outside_camera_right_ir_frame"/>
        <child link="a_bot_outside_camera_right_ir_optical_frame"/>
    </joint>
    <link
    name="a_bot_outside_camera_right_ir_optical_frame"/>
    <!-- camera color joints and links -->
    <joint name="a_bot_outside_camera_color_joint" type="fixed">
        <origin rpy="0 0 0" xyz="0 0.015 0"/>
        <parent link="a_bot_outside_camera_depth_frame"/>
        <child link="a_bot_outside_camera_color_frame"/>
    </joint>
    <link name="a_bot_outside_camera_color_frame"/>
    <joint name="a_bot_outside_camera_color_optical_joint" type="fixed">
        <origin rpy="-1.57079632679 0 -1.57079632679" xyz="0 0 0"/>
        <parent link="a_bot_outside_camera_color_frame"/>
        <child link="a_bot_outside_camera_color_optical_frame"/>
    </joint>
    <link
    name="a_bot_outside_camera_color_optical_frame"/>
    <!-- Add an additional link to plan with. Oriented like the UR ee_link frame. -->
    <joint name="a_bot_robotiq_85_tip_link_joint" type="fixed">
        <parent link="a_bot_robotiq_140_base_link"/>
        <child link="a_bot_robotiq_85_tip_link"/>
        <origin rpy="0.0 0.0 0.0" xyz="0.246 0.0 0.0"/>
    </joint>
    <link name="a_bot_robotiq_85_tip_link"/>
    <!-- ========= -->
    <!-- Add screw tool tip frames. X-axis points along the screw into the hole. -->
    <!-- Offset of the gripper tooltips -->
        <joint name="a_bot_tool_intermediate_joint" type="fixed"> <parent link="a_bot_robotiq_85_tip_link"/>
        <child link="a_bot_tool_intermediate_link"/>
        <origin rpy="3.14159265359 -1.0471975512 0" xyz="-.03 0 0"/>
    </joint>
    <link name="a_bot_tool_intermediate_link"/>
    <joint name="a_bot_robotiq_85_nut_tool_m6_tip_joint" type="fixed">
        <parent link="a_bot_tool_intermediate_link"/>
        <child link="a_bot_nut_tool_m6_tip_link"/>
        <origin rpy="0 0 0" xyz="0.107 0 -0.0075 "/>
    </joint>
    <link name="a_bot_nut_tool_m6_tip_link"/>
    <joint name="a_bot_robotiq_85_screw_tool_m4_tip_joint" type="fixed">
        <parent link="a_bot_tool_intermediate_link"/>
        <child link="a_bot_screw_tool_m4_tip_link"/>
        <origin rpy="0 0 0" xyz=".141 0 0.005 "/>
    </joint>
    <link name="a_bot_screw_tool_m4_tip_link"/>
    <joint name="a_bot_robotiq_85_screw_tool_m3_tip_joint" type="fixed">
        <parent link="a_bot_tool_intermediate_link"/>
        <child link="a_bot_screw_tool_m3_tip_link"/>
        <origin rpy="0 0 0" xyz=".121 0 .0055 "/>
    </joint>
    <link name="a_bot_screw_tool_m3_tip_link"/>
    <joint name="a_bot_robotiq_85_set_screw_tool_tip_joint" type="fixed">
        <parent link="a_bot_tool_intermediate_link"/>
        <child link="a_bot_set_screw_tool_tip_link"/>
        <origin rpy="0 0 0" xyz="0.058 0 0.006"/>
    </joint>
    <link
    name="a_bot_set_screw_tool_tip_link"/>
    <!-- The "world" link definition should be removed, but apparently it is necessary for Gazebo -->
    <link name="world"/>
    <joint name="world_joint" type="fixed">
        <parent link="world"/>
        <child link="a_bot_base_link"/>
        <origin rpy="0.0 0.0 0.0" xyz="0.0 0.0 0.0"/>
    </joint>
</robot>
